Workbook
Name Categorie_Ferie: OFFSET(Report_Assenze!$B$8,0,0,COUNTA(Report_Assenze!$B:$B)-4,1)
Name Categorie_Ferie: OFFSET(Report_Ferie!$B$8,0,0,COUNTA(Report_Ferie!$B:$B)-4,1)
Name DIPENDENTE: Dipendenti!$A:$A
Name FiltroDati_LIVELLO: #N/A
Name FiltroDati_QUALIFICA: #N/A
Name FiltroDati_REPARTO: #N/A
Name FiltroDati_SESSO: #N/A
Name TABELLA_DIP: Dipendenti[]
Name Valori_Ferie: OFFSET(Report_Assenze!$G$8,0,0,COUNTA(Report_Assenze!$G:$G)-4,1)
Name Valori_Ferie: OFFSET(Report_Ferie!$I$8,0,0,COUNTA(Report_Ferie!$I:$I)-4,1)

Sheet Dipendenti
A1: DIPENDENTE | B1: CODICE FISCALE | C1: DATA_NASCITA | D1: ETA' | E1: SESSO | F1: QUALIFICA | G1: REPARTO | H1: DATA_ASSUNZIONE | I1: DATA_SCADENZA | J1: DATA_CESSAZIONE | K1: ANZIANITA'_AZIEN | L1: TIPO_CONTRATTO | M1: LIVELLO | N1: FAMIGLIA_PROF | O1: ORE CONTRATTO | P1: FTE
A2: Alberto Angela | B2: ANGALB78A16C351X | C2: 16-10-1978 | D2: =YEAR(TODAY())-YEAR($C2)-IF(TODAY()<DATE(YEAR(TODAY()),MONTH($C2),DAY($C2)),1,0) -> 46 | E2: MASCHIO | F2: Responsabile IT | G2: Vendite | H2: 44013 | K2: =YEAR(TODAY())-YEAR($H2)-IF(TODAY()<DATE(YEAR(TODAY()),MONTH($H2),DAY($H2)),1,0) -> 4 | L2: tempo pieno | M2: D4 | N2: Manager | O2: 36 | P2: =IF(O2<=0,0,O2/36) -> 1 | Y2: =IF(Riepilogo!$B$1="", "", IF(ISNUMBER(SEARCH(Riepilogo!$B$1, A2)), ROW(), ""))
A3: Alessandro Bruno | B3: BRUALE68A07C351X | C3: 07-01-1968 | D3: =YEAR(TODAY())-YEAR($C3)-IF(TODAY()<DATE(YEAR(TODAY()),MONTH($C3),DAY($C3)),1,0) -> 57 | E3: MASCHIO | F3: Sviluppatore | G3: IT | H3: 42646 | K3: =YEAR(TODAY())-YEAR($H3)-IF(TODAY()<DATE(YEAR(TODAY()),MONTH($H3),DAY($H3)),1,0) -> 8 | L3: part-time | M3: D4 | N3: Staff | O3: 36 | P3: =IF(O3<=0,0,O3/36) -> 1 | Y3: =IF(Riepilogo!$B$1="", "", IF(ISNUMBER(SEARCH(Riepilogo!$B$1, A3)), ROW(), ""))
A4: Alessandro Cattelan | B4: CATALE88A12C351X | C4: 12-07-1988 | D4: =YEAR(TODAY())-YEAR($C4)-IF(TODAY()<DATE(YEAR(TODAY()),MONTH($C4),DAY($C4)),1,0) -> 36 | E4: MASCHIO | F4: Responsabile IT | G4: Finance | H4: 43983 | K4: =YEAR(TODAY())-YEAR($H4)-IF(TODAY()<DATE(YEAR(TODAY()),MONTH($H4),DAY($H4)),1,0) -> 4 | L4: tempo pieno | M4: D4 | N4: Tecnico | O4: 36 | P4: =IF(O4<=0,0,O4/36) -> 1 | Y4: =IF(Riepilogo!$B$1="", "", IF(ISNUMBER(SEARCH(Riepilogo!$B$1, A4)), ROW(), ""))
A5: Alessandro Esposito | B5: ESPALE77A22C351X | C5: 22-12-1977 | D5: =YEAR(TODAY())-YEAR($C5)-IF(TODAY()<DATE(YEAR(TODAY()),MONTH($C5),DAY($C5)),1,0) -> 47 | E5: MASCHIO | F5: HR Specialist | G5: Amministrazione | H5: 40210 | K5: =YEAR(TODAY())-YEAR($H5)-IF(TODAY()<DATE(YEAR(TODAY()),MONTH($H5),DAY($H5)),1,0) -> 15 | L5: tempo pieno | M5: B2 | N5: Tecnico | O5: 25 | P5: =IF(O5<=0,0,O5/36) -> 0.69444444 | Y5: =IF(Riepilogo!$B$1="", "", IF(ISNUMBER(SEARCH(Riepilogo!$B$1, A5)), ROW(), ""))
A6: Alessandro Fantozzi | B6: ESPALE64A07C351X | C6: 07-08-1964 | D6: =YEAR(TODAY())-YEAR($C6)-IF(TODAY()<DATE(YEAR(TODAY()),MONTH($C6),DAY($C6)),1,0) -> 60 | E6: MASCHIO | F6: Customer Support | G6: HR | H6: 43867 | K6: =YEAR(TODAY())-YEAR($H6)-IF(TODAY()<DATE(YEAR(TODAY()),MONTH($H6),DAY($H6)),1,0) -> 5 | L6: tempo pieno | M6: A1 | N6: Staff | O6: 30 | P6: =IF(O6<=0,0,O6/36) -> 0.83333333 | Y6: =IF(Riepilogo!$B$1="", "", IF(ISNUMBER(SEARCH(Riepilogo!$B$1, A6)), ROW(), ""))
A7: Alessandro Marino | B7: MARALE91A05C351X | C7: 05-05-1991 | D7: =YEAR(TODAY())-YEAR($C7)-IF(TODAY()<DATE(YEAR(TODAY()),MONTH($C7),DAY($C7)),1,0) -> 33 | E7: MASCHIO | F7: Addetto Vendite | G7: R&D | H7: 45716 | K7: =YEAR(TODAY())-YEAR($H7)-IF(TODAY()<DATE(YEAR(TODAY()),MONTH($H7),DAY($H7)),1,0) -> 0 | L7: part-time | M7: A1 | N7: Staff | O7: 25 | P7: =IF(O7<=0,0,O7/36) -> 0.69444444 | Y7: =IF(Riepilogo!$B$1="", "", IF(ISNUMBER(SEARCH(Riepilogo!$B$1, A7)), ROW(), ""))
A8: Alessandro Banfi | B8: MARALE70A01C351X | C8: 01-04-1970 | D8: =YEAR(TODAY())-YEAR($C8)-IF(TODAY()<DATE(YEAR(TODAY()),MONTH($C8),DAY($C8)),1,0) -> 55 | E8: MASCHIO | F8: Responsabile IT | G8: R&D | H8: 45566 | K8: =YEAR(TODAY())-YEAR($H8)-IF(TODAY()<DATE(YEAR(TODAY()),MONTH($H8),DAY($H8)),1,0) -> 0 | L8: part-time | M8: B2 | N8: Tecnico | O8: 36 | P8: =IF(O8<=0,0,O8/36) -> 1 | Y8: =IF(Riepilogo!$B$1="", "", IF(ISNUMBER(SEARCH(Riepilogo!$B$1, A8)), ROW(), ""))
A9: Alessandro Ricci | B9: RICALE87A05C351X | C9: 05-12-1987 | D9: =YEAR(TODAY())-YEAR($C9)-IF(TODAY()<DATE(YEAR(TODAY()),MONTH($C9),DAY($C9)),1,0) -> 37 | E9: MASCHIO | F9: Customer Support | G9: Logistica | H9: 45383 | K9: =YEAR(TODAY())-YEAR($H9)-IF(TODAY()<DATE(YEAR(TODAY()),MONTH($H9),DAY($H9)),1,0) -> 1 | L9: tempo pieno | M9: A1 | N9: Tecnico | O9: 36 | P9: =IF(O9<=0,0,O9/36) -> 1 | Y9: =IF(Riepilogo!$B$1="", "", IF(ISNUMBER(SEARCH(Riepilogo!$B$1, A9)), ROW(), ""))
A10: Andrea Bruno | B10: BRUAND73B01C351X | C10: 01-12-1973 | D10: =YEAR(TODAY())-YEAR($C10)-IF(TODAY()<DATE(YEAR(TODAY()),MONTH($C10),DAY($C10)),1,0) -> 51 | E10: FEMMINA | F10: HR Specialist | G10: Vendite | H10: 44378 | K10: =YEAR(TODAY())-YEAR($H10)-IF(TODAY()<DATE(YEAR(TODAY()),MONTH($H10),DAY($H10)),1,0) -> 3 | L10: part-time | M10: A1 | N10: Staff | O10: 36 | P10: =IF(O10<=0,0,O10/36) -> 1 | Y10: =IF(Riepilogo!$B$1="", "", IF(ISNUMBER(SEARCH(Riepilogo!$B$1, A10)), ROW(), ""))
A11: Andrea Colombo | B11: COLAND97B04C351X | C11: 04-09-1997 | D11: =YEAR(TODAY())-YEAR($C11)-IF(TODAY()<DATE(YEAR(TODAY()),MONTH($C11),DAY($C11)),1,0) -> 27 | E11: FEMMINA | F11: Customer Support | G11: HR | H11: 45021 | K11: =YEAR(TODAY())-YEAR($H11)-IF(TODAY()<DATE(YEAR(TODAY()),MONTH($H11),DAY($H11)),1,0) -> 2 | L11: part-time | M11: C3 | N11: Tecnico | O11: 36 | P11: =IF(O11<=0,0,O11/36) -> 1 | Y11: =IF(Riepilogo!$B$1="", "", IF(ISNUMBER(SEARCH(Riepilogo!$B$1, A11)), ROW(), ""))
A12: Andrea Costa | B12: COSAND92B04C351X | C12: 04-02-1992 | D12: =YEAR(TODAY())-YEAR($C12)-IF(TODAY()<DATE(YEAR(TODAY()),MONTH($C12),DAY($C12)),1,0) -> 33 | E12: FEMMINA | F12: Customer Support | G12: IT | H12: 44621 | K12: =YEAR(TODAY())-YEAR($H12)-IF(TODAY()<DATE(YEAR(TODAY()),MONTH($H12),DAY($H12)),1,0) -> 3 | L12: tempo pieno | M12: C3 | N12: Staff | O12: 30 | P12: =IF(O12<=0,0,O12/36) -> 0.83333333 | Y12: =IF(Riepilogo!$B$1="", "", IF(ISNUMBER(SEARCH(Riepilogo!$B$1, A12)), ROW(), ""))
A13: Andrea Greco | B13: GREAND00B25C351X | C13: 25-06-2000 | D13: =YEAR(TODAY())-YEAR($C13)-IF(TODAY()<DATE(YEAR(TODAY()),MONTH($C13),DAY($C13)),1,0) -> 24 | E13: FEMMINA | F13: Customer Support | G13: Finance | H13: 45709 | K13: =YEAR(TODAY())-YEAR($H13)-IF(TODAY()<DATE(YEAR(TODAY()),MONTH($H13),DAY($H13)),1,0) -> 0 | L13: part-time | M13: D4 | N13: Manager | O13: 25 | P13: =IF(O13<=0,0,O13/36) -> 0.69444444 | Y13: =IF(Riepilogo!$B$1="", "", IF(ISNUMBER(SEARCH(Riepilogo!$B$1, A13)), ROW(), ""))
... A101: Virginia Raggi | B101: RAGVIR71B30C351X | C101: 30-06-1971 | D101: =YEAR(TODAY())-YEAR($C101)-IF(TODAY()<DATE(YEAR(TODAY()),MONTH($C101),DAY($C101)),1,0) -> 53 | E101: FEMMINA | F101: Responsabile IT | G101: HR | H101: 44543 | K101: =YEAR(TODAY())-YEAR($H101)-IF(TODAY()<DATE(YEAR(TODAY()),MONTH($H101),DAY($H101)),1,0) -> 3 | L101: tempo pieno | M101: D4 | N101: Manager | O101: 36 | P101: =IF(O101<=0,0,O101/36) -> 1 | Y101: =IF(Riepilogo!$B$1="", "", IF(ISNUMBER(SEARCH(Riepilogo!$B$1, A101)), ROW(), ""))
Y102: =IF(Riepilogo!$B$1="", "", IF(ISNUMBER(SEARCH(Riepilogo!$B$1, A102)), ROW(), ""))
Y103: =IF(Riepilogo!$B$1="", "", IF(ISNUMBER(SEARCH(Riepilogo!$B$1, A103)), ROW(), ""))
Y104: =IF(Riepilogo!$B$1="", "", IF(ISNUMBER(SEARCH(Riepilogo!$B$1, A104)), ROW(), ""))
Y105: =IF(Riepilogo!$B$1="", "", IF(ISNUMBER(SEARCH(Riepilogo!$B$1, A105)), ROW(), ""))

Sheet Riepilogo
A1: INSERISCI NOME DIPENDENTE | B1: elena
B4: DIPENDENTE | C4: CODICE FISCALE | D4: DATA_NASCITA | E4: ETA' | F4: SESSO | G4: QUALIFICA | H4: REPARTO | I4: DATA_ASSUNZIONE | J4: DATA_TERMINE | K4: DATA_CESS_DECORRENZA | L4: ANZIANITA'_AZIEN | M4: TIPO_CONTRATTO | N4: LIVELLO | O4: FAMIGLIA_PROF | P4: ORE CONTRATTO
B5: =IFERROR(INDEX(Dipendenti!A:A,SMALL(Dipendenti!$Y$2:$Y$550,ROWS($B$5:B5))), "") -> Elena Bruno | C5: {=IFERROR(INDEX(Dipendenti!B:B,SMALL(Dipendenti!$Y$2:$Y$550,ROWS($B$5:C5))), "")} -> BRUELE96B21C351X | D5: {=IFERROR(INDEX(Dipendenti!C:C,SMALL(Dipendenti!$Y$2:$Y$550,ROWS($B$5:D5))), "")} -> 21-06-1996 | E5: {=IFERROR(INDEX(Dipendenti!D:D,SMALL(Dipendenti!$Y$2:$Y$550,ROWS($B$5:E5))), "")} -> 28 | F5: {=IFERROR(INDEX(Dipendenti!E:E,SMALL(Dipendenti!$Y$2:$Y$550,ROWS($B$5:F5))), "")} -> FEMMINA | G5: {=IFERROR(INDEX(Dipendenti!F:F,SMALL(Dipendenti!$Y$2:$Y$550,ROWS($B$5:G5))), "")} -> Responsabile IT | H5: {=IFERROR(INDEX(Dipendenti!G:G,SMALL(Dipendenti!$Y$2:$Y$550,ROWS($B$5:H5))), "")} -> Marketing | I5: {=IFERROR(IF(INDEX(Dipendenti!H:H,SMALL(Dipendenti!$Y$2:$Y$550,ROWS($B$5:B5)))=0, "", INDEX(Dipendenti!H:H,SMALL(Dipendenti!$Y$2:$Y$550,ROWS($B$5:B5)))), "")} -> 45320 | J5: {=IFERROR(IF(INDEX(Dipendenti!I:I,SMALL(Dipendenti!$Y$2:$Y$550,ROWS($B$5:C5)))=0, "", INDEX(Dipendenti!I:I,SMALL(Dipendenti!$Y$2:$Y$550,ROWS($B$5:C5)))), "")} | K5: {=IFERROR(IF(INDEX(Dipendenti!J:J,SMALL(Dipendenti!$Y$2:$Y$550,ROWS($B$5:D5)))=0, "", INDEX(Dipendenti!J:J,SMALL(Dipendenti!$Y$2:$Y$550,ROWS($B$5:D5)))), "")} | L5: {=IFERROR(INDEX(Dipendenti!K:K,SMALL(Dipendenti!$Y$2:$Y$550,ROWS($B$5:L5))), "")} -> 1 | M5: {=IFERROR(INDEX(Dipendenti!L:L,SMALL(Dipendenti!$Y$2:$Y$550,ROWS($B$5:M5))), "")} -> tempo pieno | N5: {=IFERROR(INDEX(Dipendenti!M:M,SMALL(Dipendenti!$Y$2:$Y$550,ROWS($B$5:N5))), "")} -> B2 | O5: {=IFERROR(INDEX(Dipendenti!N:N,SMALL(Dipendenti!$Y$2:$Y$550,ROWS($B$5:O5))), "")} -> Staff | P5: {=IFERROR(INDEX(Dipendenti!O:O,SMALL(Dipendenti!$Y$2:$Y$550,ROWS($B$5:P5))), "")} -> 36
B6: {=IFERROR(INDEX(Dipendenti!A:A,SMALL(Dipendenti!$Y$2:$Y$550,ROWS($B$5:B6))), "")} -> Elena Scirea | C6: {=IFERROR(INDEX(Dipendenti!B:B,SMALL(Dipendenti!$Y$2:$Y$550,ROWS($B$5:C6))), "")} -> BRUELE02B11C351X | D6: {=IFERROR(INDEX(Dipendenti!C:C,SMALL(Dipendenti!$Y$2:$Y$550,ROWS($B$5:D6))), "")} -> 11-10-2002 | E6: {=IFERROR(INDEX(Dipendenti!D:D,SMALL(Dipendenti!$Y$2:$Y$550,ROWS($B$5:E6))), "")} -> 22 | F6: {=IFERROR(INDEX(Dipendenti!E:E,SMALL(Dipendenti!$Y$2:$Y$550,ROWS($B$5:F6))), "")} -> FEMMINA | G6: {=IFERROR(INDEX(Dipendenti!F:F,SMALL(Dipendenti!$Y$2:$Y$550,ROWS($B$5:G6))), "")} -> Responsabile IT | H6: {=IFERROR(INDEX(Dipendenti!G:G,SMALL(Dipendenti!$Y$2:$Y$550,ROWS($B$5:H6))), "")} -> PMO | I6: {=IFERROR(IF(INDEX(Dipendenti!H:H,SMALL(Dipendenti!$Y$2:$Y$550,ROWS($B$5:B6)))=0, "", INDEX(Dipendenti!H:H,SMALL(Dipendenti!$Y$2:$Y$550,ROWS($B$5:B6)))), "")} -> 40603 | J6: {=IFERROR(IF(INDEX(Dipendenti!I:I,SMALL(Dipendenti!$Y$2:$Y$550,ROWS($B$5:C6)))=0, "", INDEX(Dipendenti!I:I,SMALL(Dipendenti!$Y$2:$Y$550,ROWS($B$5:C6)))), "")} | K6: {=IFERROR(IF(INDEX(Dipendenti!J:J,SMALL(Dipendenti!$Y$2:$Y$550,ROWS($B$5:D6)))=0, "", INDEX(Dipendenti!J:J,SMALL(Dipendenti!$Y$2:$Y$550,ROWS($B$5:D6)))), "")} | L6: {=IFERROR(INDEX(Dipendenti!K:K,SMALL(Dipendenti!$Y$2:$Y$550,ROWS($B$5:L6))), "")} -> 14 | M6: {=IFERROR(INDEX(Dipendenti!L:L,SMALL(Dipendenti!$Y$2:$Y$550,ROWS($B$5:M6))), "")} -> part-time | N6: {=IFERROR(INDEX(Dipendenti!M:M,SMALL(Dipendenti!$Y$2:$Y$550,ROWS($B$5:N6))), "")} -> D4 | O6: {=IFERROR(INDEX(Dipendenti!N:N,SMALL(Dipendenti!$Y$2:$Y$550,ROWS($B$5:O6))), "")} -> Manager | P6: {=IFERROR(INDEX(Dipendenti!O:O,SMALL(Dipendenti!$Y$2:$Y$550,ROWS($B$5:P6))), "")} -> 36
B7: {=IFERROR(INDEX(Dipendenti!A:A,SMALL(Dipendenti!$Y$2:$Y$550,ROWS($B$5:B7))), "")} -> Elena Colombo | C7: {=IFERROR(INDEX(Dipendenti!B:B,SMALL(Dipendenti!$Y$2:$Y$550,ROWS($B$5:C7))), "")} -> COLELE95B27C351X | D7: {=IFERROR(INDEX(Dipendenti!C:C,SMALL(Dipendenti!$Y$2:$Y$550,ROWS($B$5:D7))), "")} -> 27-05-1995 | E7: {=IFERROR(INDEX(Dipendenti!D:D,SMALL(Dipendenti!$Y$2:$Y$550,ROWS($B$5:E7))), "")} -> 29 | F7: {=IFERROR(INDEX(Dipendenti!E:E,SMALL(Dipendenti!$Y$2:$Y$550,ROWS($B$5:F7))), "")} -> FEMMINA | G7: {=IFERROR(INDEX(Dipendenti!F:F,SMALL(Dipendenti!$Y$2:$Y$550,ROWS($B$5:G7))), "")} -> Sviluppatore | H7: {=IFERROR(INDEX(Dipendenti!G:G,SMALL(Dipendenti!$Y$2:$Y$550,ROWS($B$5:H7))), "")} -> R&D | I7: {=IFERROR(IF(INDEX(Dipendenti!H:H,SMALL(Dipendenti!$Y$2:$Y$550,ROWS($B$5:B7)))=0, "", INDEX(Dipendenti!H:H,SMALL(Dipendenti!$Y$2:$Y$550,ROWS($B$5:B7)))), "")} -> 42037 | J7: {=IFERROR(IF(INDEX(Dipendenti!I:I,SMALL(Dipendenti!$Y$2:$Y$550,ROWS($B$5:C7)))=0, "", INDEX(Dipendenti!I:I,SMALL(Dipendenti!$Y$2:$Y$550,ROWS($B$5:C7)))), "")} | K7: {=IFERROR(IF(INDEX(Dipendenti!J:J,SMALL(Dipendenti!$Y$2:$Y$550,ROWS($B$5:D7)))=0, "", INDEX(Dipendenti!J:J,SMALL(Dipendenti!$Y$2:$Y$550,ROWS($B$5:D7)))), "")} | L7: {=IFERROR(INDEX(Dipendenti!K:K,SMALL(Dipendenti!$Y$2:$Y$550,ROWS($B$5:L7))), "")} -> 10 | M7: {=IFERROR(INDEX(Dipendenti!L:L,SMALL(Dipendenti!$Y$2:$Y$550,ROWS($B$5:M7))), "")} -> part-time | N7: {=IFERROR(INDEX(Dipendenti!M:M,SMALL(Dipendenti!$Y$2:$Y$550,ROWS($B$5:N7))), "")} -> D4 | O7: {=IFERROR(INDEX(Dipendenti!N:N,SMALL(Dipendenti!$Y$2:$Y$550,ROWS($B$5:O7))), "")} -> Tecnico | P7: {=IFERROR(INDEX(Dipendenti!O:O,SMALL(Dipendenti!$Y$2:$Y$550,ROWS($B$5:P7))), "")} -> 36
B8: {=IFERROR(INDEX(Dipendenti!A:A,SMALL(Dipendenti!$Y$2:$Y$550,ROWS($B$5:B8))), "")} -> Elena Baggio | C8: {=IFERROR(INDEX(Dipendenti!B:B,SMALL(Dipendenti!$Y$2:$Y$550,ROWS($B$5:C8))), "")} -> COLELE91B10C351X | D8: {=IFERROR(INDEX(Dipendenti!C:C,SMALL(Dipendenti!$Y$2:$Y$550,ROWS($B$5:D8))), "")} -> 10-10-1991 | E8: {=IFERROR(INDEX(Dipendenti!D:D,SMALL(Dipendenti!$Y$2:$Y$550,ROWS($B$5:E8))), "")} -> 33 | F8: {=IFERROR(INDEX(Dipendenti!E:E,SMALL(Dipendenti!$Y$2:$Y$550,ROWS($B$5:F8))), "")} -> FEMMINA | G8: {=IFERROR(INDEX(Dipendenti!F:F,SMALL(Dipendenti!$Y$2:$Y$550,ROWS($B$5:G8))), "")} -> Analista Dati | H8: {=IFERROR(INDEX(Dipendenti!G:G,SMALL(Dipendenti!$Y$2:$Y$550,ROWS($B$5:H8))), "")} -> Logistica | I8: {=IFERROR(IF(INDEX(Dipendenti!H:H,SMALL(Dipendenti!$Y$2:$Y$550,ROWS($B$5:B8)))=0, "", INDEX(Dipendenti!H:H,SMALL(Dipendenti!$Y$2:$Y$550,ROWS($B$5:B8)))), "")} -> 42324 | J8: {=IFERROR(IF(INDEX(Dipendenti!I:I,SMALL(Dipendenti!$Y$2:$Y$550,ROWS($B$5:C8)))=0, "", INDEX(Dipendenti!I:I,SMALL(Dipendenti!$Y$2:$Y$550,ROWS($B$5:C8)))), "")} | K8: {=IFERROR(IF(INDEX(Dipendenti!J:J,SMALL(Dipendenti!$Y$2:$Y$550,ROWS($B$5:D8)))=0, "", INDEX(Dipendenti!J:J,SMALL(Dipendenti!$Y$2:$Y$550,ROWS($B$5:D8)))), "")} | L8: {=IFERROR(INDEX(Dipendenti!K:K,SMALL(Dipendenti!$Y$2:$Y$550,ROWS($B$5:L8))), "")} -> 9 | M8: {=IFERROR(INDEX(Dipendenti!L:L,SMALL(Dipendenti!$Y$2:$Y$550,ROWS($B$5:M8))), "")} -> tempo pieno | N8: {=IFERROR(INDEX(Dipendenti!M:M,SMALL(Dipendenti!$Y$2:$Y$550,ROWS($B$5:N8))), "")} -> D4 | O8: {=IFERROR(INDEX(Dipendenti!N:N,SMALL(Dipendenti!$Y$2:$Y$550,ROWS($B$5:O8))), "")} -> Tecnico | P8: {=IFERROR(INDEX(Dipendenti!O:O,SMALL(Dipendenti!$Y$2:$Y$550,ROWS($B$5:P8))), "")} -> 36
B9: {=IFERROR(INDEX(Dipendenti!A:A,SMALL(Dipendenti!$Y$2:$Y$550,ROWS($B$5:B9))), "")} -> Elena Conti | C9: {=IFERROR(INDEX(Dipendenti!B:B,SMALL(Dipendenti!$Y$2:$Y$550,ROWS($B$5:C9))), "")} -> CONELE91B21C351X | D9: {=IFERROR(INDEX(Dipendenti!C:C,SMALL(Dipendenti!$Y$2:$Y$550,ROWS($B$5:D9))), "")} -> 21-07-1991 | E9: {=IFERROR(INDEX(Dipendenti!D:D,SMALL(Dipendenti!$Y$2:$Y$550,ROWS($B$5:E9))), "")} -> 33 | F9: {=IFERROR(INDEX(Dipendenti!E:E,SMALL(Dipendenti!$Y$2:$Y$550,ROWS($B$5:F9))), "")} -> FEMMINA | G9: {=IFERROR(INDEX(Dipendenti!F:F,SMALL(Dipendenti!$Y$2:$Y$550,ROWS($B$5:G9))), "")} -> Business Analyst | H9: {=IFERROR(INDEX(Dipendenti!G:G,SMALL(Dipendenti!$Y$2:$Y$550,ROWS($B$5:H9))), "")} -> Marketing | I9: {=IFERROR(IF(INDEX(Dipendenti!H:H,SMALL(Dipendenti!$Y$2:$Y$550,ROWS($B$5:B9)))=0, "", INDEX(Dipendenti!H:H,SMALL(Dipendenti!$Y$2:$Y$550,ROWS($B$5:B9)))), "")} -> 43851 | J9: {=IFERROR(IF(INDEX(Dipendenti!I:I,SMALL(Dipendenti!$Y$2:$Y$550,ROWS($B$5:C9)))=0, "", INDEX(Dipendenti!I:I,SMALL(Dipendenti!$Y$2:$Y$550,ROWS($B$5:C9)))), "")} | K9: {=IFERROR(IF(INDEX(Dipendenti!J:J,SMALL(Dipendenti!$Y$2:$Y$550,ROWS($B$5:D9)))=0, "", INDEX(Dipendenti!J:J,SMALL(Dipendenti!$Y$2:$Y$550,ROWS($B$5:D9)))), "")} | L9: {=IFERROR(INDEX(Dipendenti!K:K,SMALL(Dipendenti!$Y$2:$Y$550,ROWS($B$5:L9))), "")} -> 5 | M9: {=IFERROR(INDEX(Dipendenti!L:L,SMALL(Dipendenti!$Y$2:$Y$550,ROWS($B$5:M9))), "")} -> part-time | N9: {=IFERROR(INDEX(Dipendenti!M:M,SMALL(Dipendenti!$Y$2:$Y$550,ROWS($B$5:N9))), "")} -> B2 | O9: {=IFERROR(INDEX(Dipendenti!N:N,SMALL(Dipendenti!$Y$2:$Y$550,ROWS($B$5:O9))), "")} -> Staff | P9: {=IFERROR(INDEX(Dipendenti!O:O,SMALL(Dipendenti!$Y$2:$Y$550,ROWS($B$5:P9))), "")} -> 36
B10: {=IFERROR(INDEX(Dipendenti!A:A,SMALL(Dipendenti!$Y$2:$Y$550,ROWS($B$5:B10))), "")} -> Elena Gallo | C10: {=IFERROR(INDEX(Dipendenti!B:B,SMALL(Dipendenti!$Y$2:$Y$550,ROWS($B$5:C10))), "")} -> GALELE95B21C351X | D10: {=IFERROR(INDEX(Dipendenti!C:C,SMALL(Dipendenti!$Y$2:$Y$550,ROWS($B$5:D10))), "")} -> 21-09-1995 | E10: {=IFERROR(INDEX(Dipendenti!D:D,SMALL(Dipendenti!$Y$2:$Y$550,ROWS($B$5:E10))), "")} -> 29 | F10: {=IFERROR(INDEX(Dipendenti!E:E,SMALL(Dipendenti!$Y$2:$Y$550,ROWS($B$5:F10))), "")} -> FEMMINA | G10: {=IFERROR(INDEX(Dipendenti!F:F,SMALL(Dipendenti!$Y$2:$Y$550,ROWS($B$5:G10))), "")} -> HR Specialist | H10: {=IFERROR(INDEX(Dipendenti!G:G,SMALL(Dipendenti!$Y$2:$Y$550,ROWS($B$5:H10))), "")} -> Amministrazione | I10: {=IFERROR(IF(INDEX(Dipendenti!H:H,SMALL(Dipendenti!$Y$2:$Y$550,ROWS($B$5:B10)))=0, "", INDEX(Dipendenti!H:H,SMALL(Dipendenti!$Y$2:$Y$550,ROWS($B$5:B10)))), "")} -> 45090 | J10: {=IFERROR(IF(INDEX(Dipendenti!I:I,SMALL(Dipendenti!$Y$2:$Y$550,ROWS($B$5:C10)))=0, "", INDEX(Dipendenti!I:I,SMALL(Dipendenti!$Y$2:$Y$550,ROWS($B$5:C10)))), "")} | K10: {=IFERROR(IF(INDEX(Dipendenti!J:J,SMALL(Dipendenti!$Y$2:$Y$550,ROWS($B$5:D10)))=0, "", INDEX(Dipendenti!J:J,SMALL(Dipendenti!$Y$2:$Y$550,ROWS($B$5:D10)))), "")} | L10: {=IFERROR(INDEX(Dipendenti!K:K,SMALL(Dipendenti!$Y$2:$Y$550,ROWS($B$5:L10))), "")} -> 1 | M10: {=IFERROR(INDEX(Dipendenti!L:L,SMALL(Dipendenti!$Y$2:$Y$550,ROWS($B$5:M10))), "")} -> tempo pieno | N10: {=IFERROR(INDEX(Dipendenti!M:M,SMALL(Dipendenti!$Y$2:$Y$550,ROWS($B$5:N10))), "")} -> A1 | O10: {=IFERROR(INDEX(Dipendenti!N:N,SMALL(Dipendenti!$Y$2:$Y$550,ROWS($B$5:O10))), "")} -> Tecnico | P10: {=IFERROR(INDEX(Dipendenti!O:O,SMALL(Dipendenti!$Y$2:$Y$550,ROWS($B$5:P10))), "")} -> 36
B11: {=IFERROR(INDEX(Dipendenti!A:A,SMALL(Dipendenti!$Y$2:$Y$550,ROWS($B$5:B11))), "")} -> Elena Ricci | C11: {=IFERROR(INDEX(Dipendenti!B:B,SMALL(Dipendenti!$Y$2:$Y$550,ROWS($B$5:C11))), "")} -> RICELE97B08C351X | D11: {=IFERROR(INDEX(Dipendenti!C:C,SMALL(Dipendenti!$Y$2:$Y$550,ROWS($B$5:D11))), "")} -> 08-06-1997 | E11: {=IFERROR(INDEX(Dipendenti!D:D,SMALL(Dipendenti!$Y$2:$Y$550,ROWS($B$5:E11))), "")} -> 27 | F11: {=IFERROR(INDEX(Dipendenti!E:E,SMALL(Dipendenti!$Y$2:$Y$550,ROWS($B$5:F11))), "")} -> FEMMINA | G11: {=IFERROR(INDEX(Dipendenti!F:F,SMALL(Dipendenti!$Y$2:$Y$550,ROWS($B$5:G11))), "")} -> Analista Dati | H11: {=IFERROR(INDEX(Dipendenti!G:G,SMALL(Dipendenti!$Y$2:$Y$550,ROWS($B$5:H11))), "")} -> Marketing | I11: {=IFERROR(IF(INDEX(Dipendenti!H:H,SMALL(Dipendenti!$Y$2:$Y$550,ROWS($B$5:B11)))=0, "", INDEX(Dipendenti!H:H,SMALL(Dipendenti!$Y$2:$Y$550,ROWS($B$5:B11)))), "")} -> 45299 | J11: {=IFERROR(IF(INDEX(Dipendenti!I:I,SMALL(Dipendenti!$Y$2:$Y$550,ROWS($B$5:C11)))=0, "", INDEX(Dipendenti!I:I,SMALL(Dipendenti!$Y$2:$Y$550,ROWS($B$5:C11)))), "")} | K11: {=IFERROR(IF(INDEX(Dipendenti!J:J,SMALL(Dipendenti!$Y$2:$Y$550,ROWS($B$5:D11)))=0, "", INDEX(Dipendenti!J:J,SMALL(Dipendenti!$Y$2:$Y$550,ROWS($B$5:D11)))), "")} | L11: {=IFERROR(INDEX(Dipendenti!K:K,SMALL(Dipendenti!$Y$2:$Y$550,ROWS($B$5:L11))), "")} -> 1 | M11: {=IFERROR(INDEX(Dipendenti!L:L,SMALL(Dipendenti!$Y$2:$Y$550,ROWS($B$5:M11))), "")} -> part-time | N11: {=IFERROR(INDEX(Dipendenti!M:M,SMALL(Dipendenti!$Y$2:$Y$550,ROWS($B$5:N11))), "")} -> C3 | O11: {=IFERROR(INDEX(Dipendenti!N:N,SMALL(Dipendenti!$Y$2:$Y$550,ROWS($B$5:O11))), "")} -> Manager | P11: {=IFERROR(INDEX(Dipendenti!O:O,SMALL(Dipendenti!$Y$2:$Y$550,ROWS($B$5:P11))), "")} -> 36
B12: {=IFERROR(INDEX(Dipendenti!A:A,SMALL(Dipendenti!$Y$2:$Y$550,ROWS($B$5:B12))), "")} -> Elena Romano | C12: {=IFERROR(INDEX(Dipendenti!B:B,SMALL(Dipendenti!$Y$2:$Y$550,ROWS($B$5:C12))), "")} -> ROMELE99B06C351X | D12: {=IFERROR(INDEX(Dipendenti!C:C,SMALL(Dipendenti!$Y$2:$Y$550,ROWS($B$5:D12))), "")} -> 06-01-1999 | E12: {=IFERROR(INDEX(Dipendenti!D:D,SMALL(Dipendenti!$Y$2:$Y$550,ROWS($B$5:E12))), "")} -> 26 | F12: {=IFERROR(INDEX(Dipendenti!E:E,SMALL(Dipendenti!$Y$2:$Y$550,ROWS($B$5:F12))), "")} -> FEMMINA | G12: {=IFERROR(INDEX(Dipendenti!F:F,SMALL(Dipendenti!$Y$2:$Y$550,ROWS($B$5:G12))), "")} -> Sviluppatore | H12: {=IFERROR(INDEX(Dipendenti!G:G,SMALL(Dipendenti!$Y$2:$Y$550,ROWS($B$5:H12))), "")} -> Amministrazione | I12: {=IFERROR(IF(INDEX(Dipendenti!H:H,SMALL(Dipendenti!$Y$2:$Y$550,ROWS($B$5:B12)))=0, "", INDEX(Dipendenti!H:H,SMALL(Dipendenti!$Y$2:$Y$550,ROWS($B$5:B12)))), "")} -> 43943 | J12: {=IFERROR(IF(INDEX(Dipendenti!I:I,SMALL(Dipendenti!$Y$2:$Y$550,ROWS($B$5:C12)))=0, "", INDEX(Dipendenti!I:I,SMALL(Dipendenti!$Y$2:$Y$550,ROWS($B$5:C12)))), "")} | K12: {=IFERROR(IF(INDEX(Dipendenti!J:J,SMALL(Dipendenti!$Y$2:$Y$550,ROWS($B$5:D12)))=0, "", INDEX(Dipendenti!J:J,SMALL(Dipendenti!$Y$2:$Y$550,ROWS($B$5:D12)))), "")} | L12: {=IFERROR(INDEX(Dipendenti!K:K,SMALL(Dipendenti!$Y$2:$Y$550,ROWS($B$5:L12))), "")} -> 5 | M12: {=IFERROR(INDEX(Dipendenti!L:L,SMALL(Dipendenti!$Y$2:$Y$550,ROWS($B$5:M12))), "")} -> part-time | N12: {=IFERROR(INDEX(Dipendenti!M:M,SMALL(Dipendenti!$Y$2:$Y$550,ROWS($B$5:N12))), "")} -> D4 | O12: {=IFERROR(INDEX(Dipendenti!N:N,SMALL(Dipendenti!$Y$2:$Y$550,ROWS($B$5:O12))), "")} -> Staff | P12: {=IFERROR(INDEX(Dipendenti!O:O,SMALL(Dipendenti!$Y$2:$Y$550,ROWS($B$5:P12))), "")} -> 36
B13: {=IFERROR(INDEX(Dipendenti!A:A,SMALL(Dipendenti!$Y$2:$Y$550,ROWS($B$5:B13))), "")} | C13: {=IFERROR(INDEX(Dipendenti!B:B,SMALL(Dipendenti!$Y$2:$Y$550,ROWS($B$5:C13))), "")} | D13: {=IFERROR(INDEX(Dipendenti!C:C,SMALL(Dipendenti!$Y$2:$Y$550,ROWS($B$5:D13))), "")} | E13: {=IFERROR(INDEX(Dipendenti!D:D,SMALL(Dipendenti!$Y$2:$Y$550,ROWS($B$5:E13))), "")} | F13: {=IFERROR(INDEX(Dipendenti!E:E,SMALL(Dipendenti!$Y$2:$Y$550,ROWS($B$5:F13))), "")} | G13: {=IFERROR(INDEX(Dipendenti!F:F,SMALL(Dipendenti!$Y$2:$Y$550,ROWS($B$5:G13))), "")} | H13: {=IFERROR(INDEX(Dipendenti!G:G,SMALL(Dipendenti!$Y$2:$Y$550,ROWS($B$5:H13))), "")} | I13: {=IFERROR(IF(INDEX(Dipendenti!H:H,SMALL(Dipendenti!$Y$2:$Y$550,ROWS($B$5:B13)))=0, "", INDEX(Dipendenti!H:H,SMALL(Dipendenti!$Y$2:$Y$550,ROWS($B$5:B13)))), "")} | J13: {=IFERROR(IF(INDEX(Dipendenti!I:I,SMALL(Dipendenti!$Y$2:$Y$550,ROWS($B$5:C13)))=0, "", INDEX(Dipendenti!I:I,SMALL(Dipendenti!$Y$2:$Y$550,ROWS($B$5:C13)))), "")} | K13: {=IFERROR(IF(INDEX(Dipendenti!J:J,SMALL(Dipendenti!$Y$2:$Y$550,ROWS($B$5:D13)))=0, "", INDEX(Dipendenti!J:J,SMALL(Dipendenti!$Y$2:$Y$550,ROWS($B$5:D13)))), "")} | L13: {=IFERROR(INDEX(Dipendenti!K:K,SMALL(Dipendenti!$Y$2:$Y$550,ROWS($B$5:L13))), "")} | M13: {=IFERROR(INDEX(Dipendenti!L:L,SMALL(Dipendenti!$Y$2:$Y$550,ROWS($B$5:M13))), "")} | N13: {=IFERROR(INDEX(Dipendenti!M:M,SMALL(Dipendenti!$Y$2:$Y$550,ROWS($B$5:N13))), "")} | O13: {=IFERROR(INDEX(Dipendenti!N:N,SMALL(Dipendenti!$Y$2:$Y$550,ROWS($B$5:O13))), "")} | P13: {=IFERROR(INDEX(Dipendenti!O:O,SMALL(Dipendenti!$Y$2:$Y$550,ROWS($B$5:P13))), "")}
B14: {=IFERROR(INDEX(Dipendenti!A:A,SMALL(Dipendenti!$Y$2:$Y$550,ROWS($B$5:B14))), "")} | C14: {=IFERROR(INDEX(Dipendenti!B:B,SMALL(Dipendenti!$Y$2:$Y$550,ROWS($B$5:C14))), "")} | D14: {=IFERROR(INDEX(Dipendenti!C:C,SMALL(Dipendenti!$Y$2:$Y$550,ROWS($B$5:D14))), "")} | E14: {=IFERROR(INDEX(Dipendenti!D:D,SMALL(Dipendenti!$Y$2:$Y$550,ROWS($B$5:E14))), "")} | F14: {=IFERROR(INDEX(Dipendenti!E:E,SMALL(Dipendenti!$Y$2:$Y$550,ROWS($B$5:F14))), "")} | G14: {=IFERROR(INDEX(Dipendenti!F:F,SMALL(Dipendenti!$Y$2:$Y$550,ROWS($B$5:G14))), "")} | H14: {=IFERROR(INDEX(Dipendenti!G:G,SMALL(Dipendenti!$Y$2:$Y$550,ROWS($B$5:H14))), "")} | I14: {=IFERROR(IF(INDEX(Dipendenti!H:H,SMALL(Dipendenti!$Y$2:$Y$550,ROWS($B$5:B14)))=0, "", INDEX(Dipendenti!H:H,SMALL(Dipendenti!$Y$2:$Y$550,ROWS($B$5:B14)))), "")} | J14: {=IFERROR(IF(INDEX(Dipendenti!I:I,SMALL(Dipendenti!$Y$2:$Y$550,ROWS($B$5:C14)))=0, "", INDEX(Dipendenti!I:I,SMALL(Dipendenti!$Y$2:$Y$550,ROWS($B$5:C14)))), "")} | K14: {=IFERROR(IF(INDEX(Dipendenti!J:J,SMALL(Dipendenti!$Y$2:$Y$550,ROWS($B$5:D14)))=0, "", INDEX(Dipendenti!J:J,SMALL(Dipendenti!$Y$2:$Y$550,ROWS($B$5:D14)))), "")} | L14: {=IFERROR(INDEX(Dipendenti!K:K,SMALL(Dipendenti!$Y$2:$Y$550,ROWS($B$5:L14))), "")} | M14: {=IFERROR(INDEX(Dipendenti!L:L,SMALL(Dipendenti!$Y$2:$Y$550,ROWS($B$5:M14))), "")} | N14: {=IFERROR(INDEX(Dipendenti!M:M,SMALL(Dipendenti!$Y$2:$Y$550,ROWS($B$5:N14))), "")} | O14: {=IFERROR(INDEX(Dipendenti!N:N,SMALL(Dipendenti!$Y$2:$Y$550,ROWS($B$5:O14))), "")} | P14: {=IFERROR(INDEX(Dipendenti!O:O,SMALL(Dipendenti!$Y$2:$Y$550,ROWS($B$5:P14))), "")}
B15: {=IFERROR(INDEX(Dipendenti!A:A,SMALL(Dipendenti!$Y$2:$Y$550,ROWS($B$5:B15))), "")} | C15: {=IFERROR(INDEX(Dipendenti!B:B,SMALL(Dipendenti!$Y$2:$Y$550,ROWS($B$5:C15))), "")} | D15: {=IFERROR(INDEX(Dipendenti!C:C,SMALL(Dipendenti!$Y$2:$Y$550,ROWS($B$5:D15))), "")} | E15: {=IFERROR(INDEX(Dipendenti!D:D,SMALL(Dipendenti!$Y$2:$Y$550,ROWS($B$5:E15))), "")} | F15: {=IFERROR(INDEX(Dipendenti!E:E,SMALL(Dipendenti!$Y$2:$Y$550,ROWS($B$5:F15))), "")} | G15: {=IFERROR(INDEX(Dipendenti!F:F,SMALL(Dipendenti!$Y$2:$Y$550,ROWS($B$5:G15))), "")} | H15: {=IFERROR(INDEX(Dipendenti!G:G,SMALL(Dipendenti!$Y$2:$Y$550,ROWS($B$5:H15))), "")} | I15: {=IFERROR(IF(INDEX(Dipendenti!H:H,SMALL(Dipendenti!$Y$2:$Y$550,ROWS($B$5:B15)))=0, "", INDEX(Dipendenti!H:H,SMALL(Dipendenti!$Y$2:$Y$550,ROWS($B$5:B15)))), "")} | J15: {=IFERROR(IF(INDEX(Dipendenti!I:I,SMALL(Dipendenti!$Y$2:$Y$550,ROWS($B$5:C15)))=0, "", INDEX(Dipendenti!I:I,SMALL(Dipendenti!$Y$2:$Y$550,ROWS($B$5:C15)))), "")} | K15: {=IFERROR(IF(INDEX(Dipendenti!J:J,SMALL(Dipendenti!$Y$2:$Y$550,ROWS($B$5:D15)))=0, "", INDEX(Dipendenti!J:J,SMALL(Dipendenti!$Y$2:$Y$550,ROWS($B$5:D15)))), "")} | L15: {=IFERROR(INDEX(Dipendenti!K:K,SMALL(Dipendenti!$Y$2:$Y$550,ROWS($B$5:L15))), "")} | M15: {=IFERROR(INDEX(Dipendenti!L:L,SMALL(Dipendenti!$Y$2:$Y$550,ROWS($B$5:M15))), "")} | N15: {=IFERROR(INDEX(Dipendenti!M:M,SMALL(Dipendenti!$Y$2:$Y$550,ROWS($B$5:N15))), "")} | O15: {=IFERROR(INDEX(Dipendenti!N:N,SMALL(Dipendenti!$Y$2:$Y$550,ROWS($B$5:O15))), "")} | P15: {=IFERROR(INDEX(Dipendenti!O:O,SMALL(Dipendenti!$Y$2:$Y$550,ROWS($B$5:P15))), "")}
B16: {=IFERROR(INDEX(Dipendenti!A:A,SMALL(Dipendenti!$Y$2:$Y$550,ROWS($B$5:B16))), "")} | C16: {=IFERROR(INDEX(Dipendenti!B:B,SMALL(Dipendenti!$Y$2:$Y$550,ROWS($B$5:C16))), "")} | D16: {=IFERROR(INDEX(Dipendenti!C:C,SMALL(Dipendenti!$Y$2:$Y$550,ROWS($B$5:D16))), "")} | E16: {=IFERROR(INDEX(Dipendenti!D:D,SMALL(Dipendenti!$Y$2:$Y$550,ROWS($B$5:E16))), "")} | F16: {=IFERROR(INDEX(Dipendenti!E:E,SMALL(Dipendenti!$Y$2:$Y$550,ROWS($B$5:F16))), "")} | G16: {=IFERROR(INDEX(Dipendenti!F:F,SMALL(Dipendenti!$Y$2:$Y$550,ROWS($B$5:G16))), "")} | H16: {=IFERROR(INDEX(Dipendenti!G:G,SMALL(Dipendenti!$Y$2:$Y$550,ROWS($B$5:H16))), "")} | I16: {=IFERROR(IF(INDEX(Dipendenti!H:H,SMALL(Dipendenti!$Y$2:$Y$550,ROWS($B$5:B16)))=0, "", INDEX(Dipendenti!H:H,SMALL(Dipendenti!$Y$2:$Y$550,ROWS($B$5:B16)))), "")} | J16: {=IFERROR(IF(INDEX(Dipendenti!I:I,SMALL(Dipendenti!$Y$2:$Y$550,ROWS($B$5:C16)))=0, "", INDEX(Dipendenti!I:I,SMALL(Dipendenti!$Y$2:$Y$550,ROWS($B$5:C16)))), "")} | K16: {=IFERROR(IF(INDEX(Dipendenti!J:J,SMALL(Dipendenti!$Y$2:$Y$550,ROWS($B$5:D16)))=0, "", INDEX(Dipendenti!J:J,SMALL(Dipendenti!$Y$2:$Y$550,ROWS($B$5:D16)))), "")} | L16: {=IFERROR(INDEX(Dipendenti!K:K,SMALL(Dipendenti!$Y$2:$Y$550,ROWS($B$5:L16))), "")} | M16: {=IFERROR(INDEX(Dipendenti!L:L,SMALL(Dipendenti!$Y$2:$Y$550,ROWS($B$5:M16))), "")} | N16: {=IFERROR(INDEX(Dipendenti!M:M,SMALL(Dipendenti!$Y$2:$Y$550,ROWS($B$5:N16))), "")} | O16: {=IFERROR(INDEX(Dipendenti!N:N,SMALL(Dipendenti!$Y$2:$Y$550,ROWS($B$5:O16))), "")} | P16: {=IFERROR(INDEX(Dipendenti!O:O,SMALL(Dipendenti!$Y$2:$Y$550,ROWS($B$5:P16))), "")}
B17: {=IFERROR(INDEX(Dipendenti!A:A,SMALL(Dipendenti!$Y$2:$Y$550,ROWS($B$5:B17))), "")} | C17: {=IFERROR(INDEX(Dipendenti!B:B,SMALL(Dipendenti!$Y$2:$Y$550,ROWS($B$5:C17))), "")} | D17: {=IFERROR(INDEX(Dipendenti!C:C,SMALL(Dipendenti!$Y$2:$Y$550,ROWS($B$5:D17))), "")} | E17: {=IFERROR(INDEX(Dipendenti!D:D,SMALL(Dipendenti!$Y$2:$Y$550,ROWS($B$5:E17))), "")} | F17: {=IFERROR(INDEX(Dipendenti!E:E,SMALL(Dipendenti!$Y$2:$Y$550,ROWS($B$5:F17))), "")} | G17: {=IFERROR(INDEX(Dipendenti!F:F,SMALL(Dipendenti!$Y$2:$Y$550,ROWS($B$5:G17))), "")} | H17: {=IFERROR(INDEX(Dipendenti!G:G,SMALL(Dipendenti!$Y$2:$Y$550,ROWS($B$5:H17))), "")} | I17: {=IFERROR(IF(INDEX(Dipendenti!H:H,SMALL(Dipendenti!$Y$2:$Y$550,ROWS($B$5:B17)))=0, "", INDEX(Dipendenti!H:H,SMALL(Dipendenti!$Y$2:$Y$550,ROWS($B$5:B17)))), "")} | J17: {=IFERROR(IF(INDEX(Dipendenti!I:I,SMALL(Dipendenti!$Y$2:$Y$550,ROWS($B$5:C17)))=0, "", INDEX(Dipendenti!I:I,SMALL(Dipendenti!$Y$2:$Y$550,ROWS($B$5:C17)))), "")} | K17: {=IFERROR(IF(INDEX(Dipendenti!J:J,SMALL(Dipendenti!$Y$2:$Y$550,ROWS($B$5:D17)))=0, "", INDEX(Dipendenti!J:J,SMALL(Dipendenti!$Y$2:$Y$550,ROWS($B$5:D17)))), "")} | L17: {=IFERROR(INDEX(Dipendenti!K:K,SMALL(Dipendenti!$Y$2:$Y$550,ROWS($B$5:L17))), "")} | M17: {=IFERROR(INDEX(Dipendenti!L:L,SMALL(Dipendenti!$Y$2:$Y$550,ROWS($B$5:M17))), "")} | N17: {=IFERROR(INDEX(Dipendenti!M:M,SMALL(Dipendenti!$Y$2:$Y$550,ROWS($B$5:N17))), "")} | O17: {=IFERROR(INDEX(Dipendenti!N:N,SMALL(Dipendenti!$Y$2:$Y$550,ROWS($B$5:O17))), "")} | P17: {=IFERROR(INDEX(Dipendenti!O:O,SMALL(Dipendenti!$Y$2:$Y$550,ROWS($B$5:P17))), "")}
... B40: {=IFERROR(INDEX(Dipendenti!A:A,SMALL(Dipendenti!$Y$2:$Y$550,ROWS($B$5:B40))), "")} | C40: {=IFERROR(INDEX(Dipendenti!B:B,SMALL(Dipendenti!$Y$2:$Y$550,ROWS($B$5:C40))), "")} | D40: {=IFERROR(INDEX(Dipendenti!C:C,SMALL(Dipendenti!$Y$2:$Y$550,ROWS($B$5:D40))), "")} | E40: {=IFERROR(INDEX(Dipendenti!D:D,SMALL(Dipendenti!$Y$2:$Y$550,ROWS($B$5:E40))), "")} | F40: {=IFERROR(INDEX(Dipendenti!E:E,SMALL(Dipendenti!$Y$2:$Y$550,ROWS($B$5:F40))), "")} | G40: {=IFERROR(INDEX(Dipendenti!F:F,SMALL(Dipendenti!$Y$2:$Y$550,ROWS($B$5:G40))), "")} | H40: {=IFERROR(INDEX(Dipendenti!G:G,SMALL(Dipendenti!$Y$2:$Y$550,ROWS($B$5:H40))), "")} | I40: {=IFERROR(IF(INDEX(Dipendenti!H:H,SMALL(Dipendenti!$Y$2:$Y$550,ROWS($B$5:B40)))=0, "", INDEX(Dipendenti!H:H,SMALL(Dipendenti!$Y$2:$Y$550,ROWS($B$5:B40)))), "")} | J40: {=IFERROR(IF(INDEX(Dipendenti!I:I,SMALL(Dipendenti!$Y$2:$Y$550,ROWS($B$5:C40)))=0, "", INDEX(Dipendenti!I:I,SMALL(Dipendenti!$Y$2:$Y$550,ROWS($B$5:C40)))), "")} | K40: {=IFERROR(IF(INDEX(Dipendenti!J:J,SMALL(Dipendenti!$Y$2:$Y$550,ROWS($B$5:D40)))=0, "", INDEX(Dipendenti!J:J,SMALL(Dipendenti!$Y$2:$Y$550,ROWS($B$5:D40)))), "")} | L40: {=IFERROR(INDEX(Dipendenti!K:K,SMALL(Dipendenti!$Y$2:$Y$550,ROWS($B$5:L40))), "")} | M40: {=IFERROR(INDEX(Dipendenti!L:L,SMALL(Dipendenti!$Y$2:$Y$550,ROWS($B$5:M40))), "")} | N40: {=IFERROR(INDEX(Dipendenti!M:M,SMALL(Dipendenti!$Y$2:$Y$550,ROWS($B$5:N40))), "")} | O40: {=IFERROR(INDEX(Dipendenti!N:N,SMALL(Dipendenti!$Y$2:$Y$550,ROWS($B$5:O40))), "")} | P40: {=IFERROR(INDEX(Dipendenti!O:O,SMALL(Dipendenti!$Y$2:$Y$550,ROWS($B$5:P40))), "")}

Sheet Dashboard
B1: Dashboard Interattiva HR
C4: Media Età | F4: Media Seniority
C5: =GETPIVOTDATA("ETA'",Media!$A$3) -> 41.46 | F5: =GETPIVOTDATA("ANZIANITA'_AZIEN",Media!$A$6) -> 6.78
B10: Età | C10: Conteggio
B11: 20-24 | C11: 6
B12: 25-29 | C12: 13
B13: 30-34 | C13: 13
B14: 35-39 | C14: 19
B15: 40-44 | C15: 5
B16: 45-49 | C16: 14
B17: 50-54 | C17: 14
B18: 55-59 | C18: 13
B19: 60-64 | C19: 3
B20: Tot | C20: 100
B30: Sesso | C30: Conteggio | N30: Contratto | O30: Conteggio
B31: FEMMINA | C31: 60 | N31: tempo pieno | O31: 49
B32: MASCHIO | C32: 40 | N32: part-time | O32: 51
B33: Tot | C33: 100 | N33: Tot | O33: 100
F48: Livello | G48: Conteggio
F49: A1 | G49: 29
F50: B2 | G50: 19
F51: C3 | G51: 20
F52: D4 | G52: 32
F53: Tot | G53: 100

Sheet Report_Ferie
C2: Data rif saldi | D2: 45658 | F2: h/ferie/mese | G2: 20.38
C3: Proiezione al | D3: 45658
C4: Reparto | D4: Amministrazione
I6: =SUM(I8:I50) -> 284.41667 | J6: =SUM(J8:J50) -> 42.925722
C7: FERIE_AP | D7: ="FERIE MATURATE AL " &TEXT($D$3,"gg/mm/aaaa") -> FERIE MATURATE AL 01/01/2025 | E7: ="CHIUSURE AZIENDALI AL " &TEXT($D$3,"gg/mm/aaaa") -> CHIUSURE AZIENDALI AL 01/01/2025 | F7: ="FERIE GODUTE AL " &TEXT($D$3,"gg/mm/aaaa") -> FERIE GODUTE AL 01/01/2025 | G7: ="FERIE GODUTE GG EQUIVALENTI AL " & TEXT($D$3, "gg/mm/aaaa") -> FERIE GODUTE GG EQUIVALENTI AL 01/01/2025 | H7: ="FERIE PIANIFICATE AL "&TEXT($D$3,"gg/mm/aaaa") -> FERIE PIANIFICATE AL 01/01/2025 | I7: ="PROIEZIONE FERIE AL "&TEXT($D$3,"GG/MM/AAAA") -> PROIEZIONE FERIE AL 01/01/2025 | J7: ="GG EQUIVALENTI AL "&TEXT($D$3,"GG/MM/AAAA") -> GG EQUIVALENTI AL 01/01/2025
B8: {=IFERROR(INDEX(Dipendenti!A$2:A$548, SMALL(IF( (Dipendenti!G$2:G$548 = $D$4) * (Dipendenti!G$2:G$548 <> "") * (Dipendenti!L$2:L$548 <> "Lib Prof") * (IF(Dipendenti!J$2:J$548 = "", TRUE, Dipendenti!J$2:J$548 >= $D$3)), ROW(Dipendenti!A$2:A$548) - ROW(Dipendenti!A$2) + 1), ROW(A1))), "")} -> Alessandro Esposito | C8: =IFERROR(VLOOKUP($B8,SaldiFerie!A:C,3,FALSE),"") -> -8.3333333 | D8: =IF(B8="","",IF(INDEX(Dipendenti!H:H,MATCH(B8,Dipendenti!A:A,0))<$D$2, (MONTH($D$3)-MONTH($D$2))*2.83*(INDEX(Dipendenti!O:O,MATCH(B8,Dipendenti!A:A,0))/6), IF(DAY(INDEX(Dipendenti!H:H,MATCH(B8,Dipendenti!A:A,0)))<15, (MONTH($D$3)-MONTH(INDEX(Dipendenti!H:H,MATCH(B8,Dipendenti!A:A,0))))*2.83*(INDEX(Dipendenti!O:O,MATCH(B8,Dipendenti!A:A,0))/6), ((MONTH($D$3)-MONTH(INDEX(Dipendenti!H:H,MATCH(B8,Dipendenti!A:A,0))))*2.83*(INDEX(Dipendenti!O:O,MATCH(B8,Dipendenti!A:A,0))/6)+ ((_xlfn.DAYS(EOMONTH(INDEX(Dipendenti!H:H,MATCH(B8,Dipendenti!A:A,0)),0), INDEX(Dipendenti!H:H,MATCH(B8,Dipendenti!A:A,0)))+1)/(_xlfn.DAYS(EOMONTH(INDEX(Dipendenti!H:H,MATCH(B8,Dipendenti!A:A,0)),0), EOMONTH(INDEX(Dipendenti!H:H,MATCH(B8,Dipendenti!A:A,0)),-1)+1)+1) )*2.83*(INDEX(Dipendenti!O:O,MATCH(B8,Dipendenti!A:A,0))/6) ) ) )) -> 0 | E8: =IF($B8="","",COUNTIFS(ChiusureAziendali!$A:$A,">"&$D$2,ChiusureAziendali!$A:$A,"<="&$D$3)*7.12) -> 0 | F8: =IF($B8="","",SUMIFS(Registro_Ferie!$C:$C, Registro_Ferie!$A:$A,$B8, Registro_Ferie!$D:$D, "ferie_g", Registro_Ferie!$B:$B, ">="&$D$2, Registro_Ferie!$C:$C, "<="&$D$3) + SUMIFS(Registro_Ferie!$C:$C, Registro_Ferie!$A:$A,$B8, Registro_Ferie!$D:$D, "ferie_g", Registro_Ferie!$B:$B, ">="&$D$2, Registro_Ferie!$B:$B, "<="&$D$3)) -> 182.72 | G8: =IFERROR($F8 / (INDEX(Dipendenti!$O:$O, MATCH($B8, Dipendenti!$A:$A, 0)) / 6), "") -> 43.8528 | H8: =IF($B8="","",SUMIFS(Registro_Ferie!$C:$C, Registro_Ferie!$A:$A,$B8, Registro_Ferie!$D:$D, "ferie", Registro_Ferie!$B:$B, ">="&$D$2, Registro_Ferie!$C:$C, "<="&$D$3) + SUMIFS(Registro_Ferie!$C:$C, Registro_Ferie!$A:$A,$B8, Registro_Ferie!$D:$D, "ferie", Registro_Ferie!$B:$B, ">="&$D$2, Registro_Ferie!$B:$B, "<="&$D$3)) -> 0 | I8: =IFERROR(C8+D8-E8-F8-H8,"") -> -191.05333 | J8: =IFERROR($I8 / (INDEX(Dipendenti!$O:$O, MATCH($B8, Dipendenti!$A:$A, 0)) / 5), "") -> -38.210667
B9: {=IFERROR(INDEX(Dipendenti!A$2:A$548, SMALL(IF( (Dipendenti!G$2:G$548 = $D$4) * (Dipendenti!G$2:G$548 <> "") * (Dipendenti!L$2:L$548 <> "Lib Prof") * (IF(Dipendenti!J$2:J$548 = "", TRUE, Dipendenti!J$2:J$548 >= $D$3)), ROW(Dipendenti!A$2:A$548) - ROW(Dipendenti!A$2) + 1), ROW(A2))), "")} -> Andrea Totti | C9: =IFERROR(VLOOKUP($B9,SaldiFerie!A:C,3,FALSE),"") -> 162.5 | D9: =IF(B9="","",IF(INDEX(Dipendenti!H:H,MATCH(B9,Dipendenti!A:A,0))<$D$2, (MONTH($D$3)-MONTH($D$2))*2.83*(INDEX(Dipendenti!O:O,MATCH(B9,Dipendenti!A:A,0))/6), IF(DAY(INDEX(Dipendenti!H:H,MATCH(B9,Dipendenti!A:A,0)))<15, (MONTH($D$3)-MONTH(INDEX(Dipendenti!H:H,MATCH(B9,Dipendenti!A:A,0))))*2.83*(INDEX(Dipendenti!O:O,MATCH(B9,Dipendenti!A:A,0))/6), ((MONTH($D$3)-MONTH(INDEX(Dipendenti!H:H,MATCH(B9,Dipendenti!A:A,0))))*2.83*(INDEX(Dipendenti!O:O,MATCH(B9,Dipendenti!A:A,0))/6)+ ((_xlfn.DAYS(EOMONTH(INDEX(Dipendenti!H:H,MATCH(B9,Dipendenti!A:A,0)),0), INDEX(Dipendenti!H:H,MATCH(B9,Dipendenti!A:A,0)))+1)/(_xlfn.DAYS(EOMONTH(INDEX(Dipendenti!H:H,MATCH(B9,Dipendenti!A:A,0)),0), EOMONTH(INDEX(Dipendenti!H:H,MATCH(B9,Dipendenti!A:A,0)),-1)+1)+1) )*2.83*(INDEX(Dipendenti!O:O,MATCH(B9,Dipendenti!A:A,0))/6) ) ) )) -> 0 | E9: =IF($B9="","",COUNTIFS(ChiusureAziendali!$A:$A,">"&$D$2,ChiusureAziendali!$A:$A,"<="&$D$3)*7.12) -> 0 | F9: =IF($B9="","",SUMIFS(Registro_Ferie!$C:$C, Registro_Ferie!$A:$A,$B9, Registro_Ferie!$D:$D, "ferie_g", Registro_Ferie!$B:$B, ">="&$D$2, Registro_Ferie!$C:$C, "<="&$D$3) + SUMIFS(Registro_Ferie!$C:$C, Registro_Ferie!$A:$A,$B9, Registro_Ferie!$D:$D, "ferie_g", Registro_Ferie!$B:$B, ">="&$D$2, Registro_Ferie!$B:$B, "<="&$D$3)) -> 0 | G9: =IFERROR($F9 / (INDEX(Dipendenti!$O:$O, MATCH($B9, Dipendenti!$A:$A, 0)) / 6), "") -> 0 | H9: =IF($B9="","",SUMIFS(Registro_Ferie!$C:$C, Registro_Ferie!$A:$A,$B9, Registro_Ferie!$D:$D, "ferie", Registro_Ferie!$B:$B, ">="&$D$2, Registro_Ferie!$C:$C, "<="&$D$3) + SUMIFS(Registro_Ferie!$C:$C, Registro_Ferie!$A:$A,$B9, Registro_Ferie!$D:$D, "ferie", Registro_Ferie!$B:$B, ">="&$D$2, Registro_Ferie!$B:$B, "<="&$D$3)) -> 0 | I9: =IFERROR(C9+D9-E9-F9-H9,"") -> 162.5 | J9: =IFERROR($I9 / (INDEX(Dipendenti!$O:$O, MATCH($B9, Dipendenti!$A:$A, 0)) / 5), "") -> 32.5
B10: {=IFERROR(INDEX(Dipendenti!A$2:A$548, SMALL(IF( (Dipendenti!G$2:G$548 = $D$4) * (Dipendenti!G$2:G$548 <> "") * (Dipendenti!L$2:L$548 <> "Lib Prof") * (IF(Dipendenti!J$2:J$548 = "", TRUE, Dipendenti!J$2:J$548 >= $D$3)), ROW(Dipendenti!A$2:A$548) - ROW(Dipendenti!A$2) + 1), ROW(A3))), "")} -> Chiara Romano | C10: =IFERROR(VLOOKUP($B10,SaldiFerie!A:C,3,FALSE),"") -> 245 | D10: =IF(B10="","",IF(INDEX(Dipendenti!H:H,MATCH(B10,Dipendenti!A:A,0))<$D$2, (MONTH($D$3)-MONTH($D$2))*2.83*(INDEX(Dipendenti!O:O,MATCH(B10,Dipendenti!A:A,0))/6), IF(DAY(INDEX(Dipendenti!H:H,MATCH(B10,Dipendenti!A:A,0)))<15, (MONTH($D$3)-MONTH(INDEX(Dipendenti!H:H,MATCH(B10,Dipendenti!A:A,0))))*2.83*(INDEX(Dipendenti!O:O,MATCH(B10,Dipendenti!A:A,0))/6), ((MONTH($D$3)-MONTH(INDEX(Dipendenti!H:H,MATCH(B10,Dipendenti!A:A,0))))*2.83*(INDEX(Dipendenti!O:O,MATCH(B10,Dipendenti!A:A,0))/6)+ ((_xlfn.DAYS(EOMONTH(INDEX(Dipendenti!H:H,MATCH(B10,Dipendenti!A:A,0)),0), INDEX(Dipendenti!H:H,MATCH(B10,Dipendenti!A:A,0)))+1)/(_xlfn.DAYS(EOMONTH(INDEX(Dipendenti!H:H,MATCH(B10,Dipendenti!A:A,0)),0), EOMONTH(INDEX(Dipendenti!H:H,MATCH(B10,Dipendenti!A:A,0)),-1)+1)+1) )*2.83*(INDEX(Dipendenti!O:O,MATCH(B10,Dipendenti!A:A,0))/6) ) ) )) -> 0 | E10: =IF($B10="","",COUNTIFS(ChiusureAziendali!$A:$A,">"&$D$2,ChiusureAziendali!$A:$A,"<="&$D$3)*7.12) -> 0 | F10: =IF($B10="","",SUMIFS(Registro_Ferie!$C:$C, Registro_Ferie!$A:$A,$B10, Registro_Ferie!$D:$D, "ferie_g", Registro_Ferie!$B:$B, ">="&$D$2, Registro_Ferie!$C:$C, "<="&$D$3) + SUMIFS(Registro_Ferie!$C:$C, Registro_Ferie!$A:$A,$B10, Registro_Ferie!$D:$D, "ferie_g", Registro_Ferie!$B:$B, ">="&$D$2, Registro_Ferie!$B:$B, "<="&$D$3)) -> 58.94 | G10: =IFERROR($F10 / (INDEX(Dipendenti!$O:$O, MATCH($B10, Dipendenti!$A:$A, 0)) / 6), "") -> 11.788 | H10: =IF($B10="","",SUMIFS(Registro_Ferie!$C:$C, Registro_Ferie!$A:$A,$B10, Registro_Ferie!$D:$D, "ferie", Registro_Ferie!$B:$B, ">="&$D$2, Registro_Ferie!$C:$C, "<="&$D$3) + SUMIFS(Registro_Ferie!$C:$C, Registro_Ferie!$A:$A,$B10, Registro_Ferie!$D:$D, "ferie", Registro_Ferie!$B:$B, ">="&$D$2, Registro_Ferie!$B:$B, "<="&$D$3)) -> 0 | I10: =IFERROR(C10+D10-E10-F10-H10,"") -> 186.06 | J10: =IFERROR($I10 / (INDEX(Dipendenti!$O:$O, MATCH($B10, Dipendenti!$A:$A, 0)) / 5), "") -> 31.01
B11: {=IFERROR(INDEX(Dipendenti!A$2:A$548, SMALL(IF( (Dipendenti!G$2:G$548 = $D$4) * (Dipendenti!G$2:G$548 <> "") * (Dipendenti!L$2:L$548 <> "Lib Prof") * (IF(Dipendenti!J$2:J$548 = "", TRUE, Dipendenti!J$2:J$548 >= $D$3)), ROW(Dipendenti!A$2:A$548) - ROW(Dipendenti!A$2) + 1), ROW(A4))), "")} -> Elena Gallo | C11: =IFERROR(VLOOKUP($B11,SaldiFerie!A:C,3,FALSE),"") -> 120 | D11: =IF(B11="","",IF(INDEX(Dipendenti!H:H,MATCH(B11,Dipendenti!A:A,0))<$D$2, (MONTH($D$3)-MONTH($D$2))*2.83*(INDEX(Dipendenti!O:O,MATCH(B11,Dipendenti!A:A,0))/6), IF(DAY(INDEX(Dipendenti!H:H,MATCH(B11,Dipendenti!A:A,0)))<15, (MONTH($D$3)-MONTH(INDEX(Dipendenti!H:H,MATCH(B11,Dipendenti!A:A,0))))*2.83*(INDEX(Dipendenti!O:O,MATCH(B11,Dipendenti!A:A,0))/6), ((MONTH($D$3)-MONTH(INDEX(Dipendenti!H:H,MATCH(B11,Dipendenti!A:A,0))))*2.83*(INDEX(Dipendenti!O:O,MATCH(B11,Dipendenti!A:A,0))/6)+ ((_xlfn.DAYS(EOMONTH(INDEX(Dipendenti!H:H,MATCH(B11,Dipendenti!A:A,0)),0), INDEX(Dipendenti!H:H,MATCH(B11,Dipendenti!A:A,0)))+1)/(_xlfn.DAYS(EOMONTH(INDEX(Dipendenti!H:H,MATCH(B11,Dipendenti!A:A,0)),0), EOMONTH(INDEX(Dipendenti!H:H,MATCH(B11,Dipendenti!A:A,0)),-1)+1)+1) )*2.83*(INDEX(Dipendenti!O:O,MATCH(B11,Dipendenti!A:A,0))/6) ) ) )) -> 0 | E11: =IF($B11="","",COUNTIFS(ChiusureAziendali!$A:$A,">"&$D$2,ChiusureAziendali!$A:$A,"<="&$D$3)*7.12) -> 0 | F11: =IF($B11="","",SUMIFS(Registro_Ferie!$C:$C, Registro_Ferie!$A:$A,$B11, Registro_Ferie!$D:$D, "ferie_g", Registro_Ferie!$B:$B, ">="&$D$2, Registro_Ferie!$C:$C, "<="&$D$3) + SUMIFS(Registro_Ferie!$C:$C, Registro_Ferie!$A:$A,$B11, Registro_Ferie!$D:$D, "ferie_g", Registro_Ferie!$B:$B, ">="&$D$2, Registro_Ferie!$B:$B, "<="&$D$3)) -> 0 | G11: =IFERROR($F11 / (INDEX(Dipendenti!$O:$O, MATCH($B11, Dipendenti!$A:$A, 0)) / 6), "") -> 0 | H11: =IF($B11="","",SUMIFS(Registro_Ferie!$C:$C, Registro_Ferie!$A:$A,$B11, Registro_Ferie!$D:$D, "ferie", Registro_Ferie!$B:$B, ">="&$D$2, Registro_Ferie!$C:$C, "<="&$D$3) + SUMIFS(Registro_Ferie!$C:$C, Registro_Ferie!$A:$A,$B11, Registro_Ferie!$D:$D, "ferie", Registro_Ferie!$B:$B, ">="&$D$2, Registro_Ferie!$B:$B, "<="&$D$3)) -> 0 | I11: =IFERROR(C11+D11-E11-F11-H11,"") -> 120 | J11: =IFERROR($I11 / (INDEX(Dipendenti!$O:$O, MATCH($B11, Dipendenti!$A:$A, 0)) / 5), "") -> 16.666667
B12: {=IFERROR(INDEX(Dipendenti!A$2:A$548, SMALL(IF( (Dipendenti!G$2:G$548 = $D$4) * (Dipendenti!G$2:G$548 <> "") * (Dipendenti!L$2:L$548 <> "Lib Prof") * (IF(Dipendenti!J$2:J$548 = "", TRUE, Dipendenti!J$2:J$548 >= $D$3)), ROW(Dipendenti!A$2:A$548) - ROW(Dipendenti!A$2) + 1), ROW(A5))), "")} -> Elena Romano | C12: =IFERROR(VLOOKUP($B12,SaldiFerie!A:C,3,FALSE),"") -> 252 | D12: =IF(B12="","",IF(INDEX(Dipendenti!H:H,MATCH(B12,Dipendenti!A:A,0))<$D$2, (MONTH($D$3)-MONTH($D$2))*2.83*(INDEX(Dipendenti!O:O,MATCH(B12,Dipendenti!A:A,0))/6), IF(DAY(INDEX(Dipendenti!H:H,MATCH(B12,Dipendenti!A:A,0)))<15, (MONTH($D$3)-MONTH(INDEX(Dipendenti!H:H,MATCH(B12,Dipendenti!A:A,0))))*2.83*(INDEX(Dipendenti!O:O,MATCH(B12,Dipendenti!A:A,0))/6), ((MONTH($D$3)-MONTH(INDEX(Dipendenti!H:H,MATCH(B12,Dipendenti!A:A,0))))*2.83*(INDEX(Dipendenti!O:O,MATCH(B12,Dipendenti!A:A,0))/6)+ ((_xlfn.DAYS(EOMONTH(INDEX(Dipendenti!H:H,MATCH(B12,Dipendenti!A:A,0)),0), INDEX(Dipendenti!H:H,MATCH(B12,Dipendenti!A:A,0)))+1)/(_xlfn.DAYS(EOMONTH(INDEX(Dipendenti!H:H,MATCH(B12,Dipendenti!A:A,0)),0), EOMONTH(INDEX(Dipendenti!H:H,MATCH(B12,Dipendenti!A:A,0)),-1)+1)+1) )*2.83*(INDEX(Dipendenti!O:O,MATCH(B12,Dipendenti!A:A,0))/6) ) ) )) -> 0 | E12: =IF($B12="","",COUNTIFS(ChiusureAziendali!$A:$A,">"&$D$2,ChiusureAziendali!$A:$A,"<="&$D$3)*7.12) -> 0 | F12: =IF($B12="","",SUMIFS(Registro_Ferie!$C:$C, Registro_Ferie!$A:$A,$B12, Registro_Ferie!$D:$D, "ferie_g", Registro_Ferie!$B:$B, ">="&$D$2, Registro_Ferie!$C:$C, "<="&$D$3) + SUMIFS(Registro_Ferie!$C:$C, Registro_Ferie!$A:$A,$B12, Registro_Ferie!$D:$D, "ferie_g", Registro_Ferie!$B:$B, ">="&$D$2, Registro_Ferie!$B:$B, "<="&$D$3)) -> 102.53 | G12: =IFERROR($F12 / (INDEX(Dipendenti!$O:$O, MATCH($B12, Dipendenti!$A:$A, 0)) / 6), "") -> 17.088333 | H12: =IF($B12="","",SUMIFS(Registro_Ferie!$C:$C, Registro_Ferie!$A:$A,$B12, Registro_Ferie!$D:$D, "ferie", Registro_Ferie!$B:$B, ">="&$D$2, Registro_Ferie!$C:$C, "<="&$D$3) + SUMIFS(Registro_Ferie!$C:$C, Registro_Ferie!$A:$A,$B12, Registro_Ferie!$D:$D, "ferie", Registro_Ferie!$B:$B, ">="&$D$2, Registro_Ferie!$B:$B, "<="&$D$3)) -> 0 | I12: =IFERROR(C12+D12-E12-F12-H12,"") -> 149.47 | J12: =IFERROR($I12 / (INDEX(Dipendenti!$O:$O, MATCH($B12, Dipendenti!$A:$A, 0)) / 5), "") -> 20.759722
B13: {=IFERROR(INDEX(Dipendenti!A$2:A$548, SMALL(IF( (Dipendenti!G$2:G$548 = $D$4) * (Dipendenti!G$2:G$548 <> "") * (Dipendenti!L$2:L$548 <> "Lib Prof") * (IF(Dipendenti!J$2:J$548 = "", TRUE, Dipendenti!J$2:J$548 >= $D$3)), ROW(Dipendenti!A$2:A$548) - ROW(Dipendenti!A$2) + 1), ROW(A6))), "")} -> Francesco Totti | C13: =IFERROR(VLOOKUP($B13,SaldiFerie!A:C,3,FALSE),"") -> 90 | D13: =IF(B13="","",IF(INDEX(Dipendenti!H:H,MATCH(B13,Dipendenti!A:A,0))<$D$2, (MONTH($D$3)-MONTH($D$2))*2.83*(INDEX(Dipendenti!O:O,MATCH(B13,Dipendenti!A:A,0))/6), IF(DAY(INDEX(Dipendenti!H:H,MATCH(B13,Dipendenti!A:A,0)))<15, (MONTH($D$3)-MONTH(INDEX(Dipendenti!H:H,MATCH(B13,Dipendenti!A:A,0))))*2.83*(INDEX(Dipendenti!O:O,MATCH(B13,Dipendenti!A:A,0))/6), ((MONTH($D$3)-MONTH(INDEX(Dipendenti!H:H,MATCH(B13,Dipendenti!A:A,0))))*2.83*(INDEX(Dipendenti!O:O,MATCH(B13,Dipendenti!A:A,0))/6)+ ((_xlfn.DAYS(EOMONTH(INDEX(Dipendenti!H:H,MATCH(B13,Dipendenti!A:A,0)),0), INDEX(Dipendenti!H:H,MATCH(B13,Dipendenti!A:A,0)))+1)/(_xlfn.DAYS(EOMONTH(INDEX(Dipendenti!H:H,MATCH(B13,Dipendenti!A:A,0)),0), EOMONTH(INDEX(Dipendenti!H:H,MATCH(B13,Dipendenti!A:A,0)),-1)+1)+1) )*2.83*(INDEX(Dipendenti!O:O,MATCH(B13,Dipendenti!A:A,0))/6) ) ) )) -> 0 | E13: =IF($B13="","",COUNTIFS(ChiusureAziendali!$A:$A,">"&$D$2,ChiusureAziendali!$A:$A,"<="&$D$3)*7.12) -> 0 | F13: =IF($B13="","",SUMIFS(Registro_Ferie!$C:$C, Registro_Ferie!$A:$A,$B13, Registro_Ferie!$D:$D, "ferie_g", Registro_Ferie!$B:$B, ">="&$D$2, Registro_Ferie!$C:$C, "<="&$D$3) + SUMIFS(Registro_Ferie!$C:$C, Registro_Ferie!$A:$A,$B13, Registro_Ferie!$D:$D, "ferie_g", Registro_Ferie!$B:$B, ">="&$D$2, Registro_Ferie!$B:$B, "<="&$D$3)) -> 70.2 | G13: =IFERROR($F13 / (INDEX(Dipendenti!$O:$O, MATCH($B13, Dipendenti!$A:$A, 0)) / 6), "") -> 11.7 | H13: =IF($B13="","",SUMIFS(Registro_Ferie!$C:$C, Registro_Ferie!$A:$A,$B13, Registro_Ferie!$D:$D, "ferie", Registro_Ferie!$B:$B, ">="&$D$2, Registro_Ferie!$C:$C, "<="&$D$3) + SUMIFS(Registro_Ferie!$C:$C, Registro_Ferie!$A:$A,$B13, Registro_Ferie!$D:$D, "ferie", Registro_Ferie!$B:$B, ">="&$D$2, Registro_Ferie!$B:$B, "<="&$D$3)) -> 0 | I13: =IFERROR(C13+D13-E13-F13-H13,"") -> 19.8 | J13: =IFERROR($I13 / (INDEX(Dipendenti!$O:$O, MATCH($B13, Dipendenti!$A:$A, 0)) / 5), "") -> 2.75
B14: {=IFERROR(INDEX(Dipendenti!A$2:A$548, SMALL(IF( (Dipendenti!G$2:G$548 = $D$4) * (Dipendenti!G$2:G$548 <> "") * (Dipendenti!L$2:L$548 <> "Lib Prof") * (IF(Dipendenti!J$2:J$548 = "", TRUE, Dipendenti!J$2:J$548 >= $D$3)), ROW(Dipendenti!A$2:A$548) - ROW(Dipendenti!A$2) + 1), ROW(A7))), "")} -> Marco Mengoni | C14: =IFERROR(VLOOKUP($B14,SaldiFerie!A:C,3,FALSE),"") -> 36 | D14: =IF(B14="","",IF(INDEX(Dipendenti!H:H,MATCH(B14,Dipendenti!A:A,0))<$D$2, (MONTH($D$3)-MONTH($D$2))*2.83*(INDEX(Dipendenti!O:O,MATCH(B14,Dipendenti!A:A,0))/6), IF(DAY(INDEX(Dipendenti!H:H,MATCH(B14,Dipendenti!A:A,0)))<15, (MONTH($D$3)-MONTH(INDEX(Dipendenti!H:H,MATCH(B14,Dipendenti!A:A,0))))*2.83*(INDEX(Dipendenti!O:O,MATCH(B14,Dipendenti!A:A,0))/6), ((MONTH($D$3)-MONTH(INDEX(Dipendenti!H:H,MATCH(B14,Dipendenti!A:A,0))))*2.83*(INDEX(Dipendenti!O:O,MATCH(B14,Dipendenti!A:A,0))/6)+ ((_xlfn.DAYS(EOMONTH(INDEX(Dipendenti!H:H,MATCH(B14,Dipendenti!A:A,0)),0), INDEX(Dipendenti!H:H,MATCH(B14,Dipendenti!A:A,0)))+1)/(_xlfn.DAYS(EOMONTH(INDEX(Dipendenti!H:H,MATCH(B14,Dipendenti!A:A,0)),0), EOMONTH(INDEX(Dipendenti!H:H,MATCH(B14,Dipendenti!A:A,0)),-1)+1)+1) )*2.83*(INDEX(Dipendenti!O:O,MATCH(B14,Dipendenti!A:A,0))/6) ) ) )) -> 0 | E14: =IF($B14="","",COUNTIFS(ChiusureAziendali!$A:$A,">"&$D$2,ChiusureAziendali!$A:$A,"<="&$D$3)*7.12) -> 0 | F14: =IF($B14="","",SUMIFS(Registro_Ferie!$C:$C, Registro_Ferie!$A:$A,$B14, Registro_Ferie!$D:$D, "ferie_g", Registro_Ferie!$B:$B, ">="&$D$2, Registro_Ferie!$C:$C, "<="&$D$3) + SUMIFS(Registro_Ferie!$C:$C, Registro_Ferie!$A:$A,$B14, Registro_Ferie!$D:$D, "ferie_g", Registro_Ferie!$B:$B, ">="&$D$2, Registro_Ferie!$B:$B, "<="&$D$3)) -> 58.12 | G14: =IFERROR($F14 / (INDEX(Dipendenti!$O:$O, MATCH($B14, Dipendenti!$A:$A, 0)) / 6), "") -> 9.6866667 | H14: =IF($B14="","",SUMIFS(Registro_Ferie!$C:$C, Registro_Ferie!$A:$A,$B14, Registro_Ferie!$D:$D, "ferie", Registro_Ferie!$B:$B, ">="&$D$2, Registro_Ferie!$C:$C, "<="&$D$3) + SUMIFS(Registro_Ferie!$C:$C, Registro_Ferie!$A:$A,$B14, Registro_Ferie!$D:$D, "ferie", Registro_Ferie!$B:$B, ">="&$D$2, Registro_Ferie!$B:$B, "<="&$D$3)) -> 0 | I14: =IFERROR(C14+D14-E14-F14-H14,"") -> -22.12 | J14: =IFERROR($I14 / (INDEX(Dipendenti!$O:$O, MATCH($B14, Dipendenti!$A:$A, 0)) / 5), "") -> -3.0722222
B15: {=IFERROR(INDEX(Dipendenti!A$2:A$548, SMALL(IF( (Dipendenti!G$2:G$548 = $D$4) * (Dipendenti!G$2:G$548 <> "") * (Dipendenti!L$2:L$548 <> "Lib Prof") * (IF(Dipendenti!J$2:J$548 = "", TRUE, Dipendenti!J$2:J$548 >= $D$3)), ROW(Dipendenti!A$2:A$548) - ROW(Dipendenti!A$2) + 1), ROW(A8))), "")} -> Martina Gallo | C15: =IFERROR(VLOOKUP($B15,SaldiFerie!A:C,3,FALSE),"") -> 30 | D15: =IF(B15="","",IF(INDEX(Dipendenti!H:H,MATCH(B15,Dipendenti!A:A,0))<$D$2, (MONTH($D$3)-MONTH($D$2))*2.83*(INDEX(Dipendenti!O:O,MATCH(B15,Dipendenti!A:A,0))/6), IF(DAY(INDEX(Dipendenti!H:H,MATCH(B15,Dipendenti!A:A,0)))<15, (MONTH($D$3)-MONTH(INDEX(Dipendenti!H:H,MATCH(B15,Dipendenti!A:A,0))))*2.83*(INDEX(Dipendenti!O:O,MATCH(B15,Dipendenti!A:A,0))/6), ((MONTH($D$3)-MONTH(INDEX(Dipendenti!H:H,MATCH(B15,Dipendenti!A:A,0))))*2.83*(INDEX(Dipendenti!O:O,MATCH(B15,Dipendenti!A:A,0))/6)+ ((_xlfn.DAYS(EOMONTH(INDEX(Dipendenti!H:H,MATCH(B15,Dipendenti!A:A,0)),0), INDEX(Dipendenti!H:H,MATCH(B15,Dipendenti!A:A,0)))+1)/(_xlfn.DAYS(EOMONTH(INDEX(Dipendenti!H:H,MATCH(B15,Dipendenti!A:A,0)),0), EOMONTH(INDEX(Dipendenti!H:H,MATCH(B15,Dipendenti!A:A,0)),-1)+1)+1) )*2.83*(INDEX(Dipendenti!O:O,MATCH(B15,Dipendenti!A:A,0))/6) ) ) )) -> 0 | E15: =IF($B15="","",COUNTIFS(ChiusureAziendali!$A:$A,">"&$D$2,ChiusureAziendali!$A:$A,"<="&$D$3)*7.12) -> 0 | F15: =IF($B15="","",SUMIFS(Registro_Ferie!$C:$C, Registro_Ferie!$A:$A,$B15, Registro_Ferie!$D:$D, "ferie_g", Registro_Ferie!$B:$B, ">="&$D$2, Registro_Ferie!$C:$C, "<="&$D$3) + SUMIFS(Registro_Ferie!$C:$C, Registro_Ferie!$A:$A,$B15, Registro_Ferie!$D:$D, "ferie_g", Registro_Ferie!$B:$B, ">="&$D$2, Registro_Ferie!$B:$B, "<="&$D$3)) -> 76.55 | G15: =IFERROR($F15 / (INDEX(Dipendenti!$O:$O, MATCH($B15, Dipendenti!$A:$A, 0)) / 6), "") -> 12.758333 | H15: =IF($B15="","",SUMIFS(Registro_Ferie!$C:$C, Registro_Ferie!$A:$A,$B15, Registro_Ferie!$D:$D, "ferie", Registro_Ferie!$B:$B, ">="&$D$2, Registro_Ferie!$C:$C, "<="&$D$3) + SUMIFS(Registro_Ferie!$C:$C, Registro_Ferie!$A:$A,$B15, Registro_Ferie!$D:$D, "ferie", Registro_Ferie!$B:$B, ">="&$D$2, Registro_Ferie!$B:$B, "<="&$D$3)) -> 0 | I15: =IFERROR(C15+D15-E15-F15-H15,"") -> -46.55 | J15: =IFERROR($I15 / (INDEX(Dipendenti!$O:$O, MATCH($B15, Dipendenti!$A:$A, 0)) / 5), "") -> -6.4652778
B16: {=IFERROR(INDEX(Dipendenti!A$2:A$548, SMALL(IF( (Dipendenti!G$2:G$548 = $D$4) * (Dipendenti!G$2:G$548 <> "") * (Dipendenti!L$2:L$548 <> "Lib Prof") * (IF(Dipendenti!J$2:J$548 = "", TRUE, Dipendenti!J$2:J$548 >= $D$3)), ROW(Dipendenti!A$2:A$548) - ROW(Dipendenti!A$2) + 1), ROW(A9))), "")} -> Matteo Sinner | C16: =IFERROR(VLOOKUP($B16,SaldiFerie!A:C,3,FALSE),"") -> 180 | D16: =IF(B16="","",IF(INDEX(Dipendenti!H:H,MATCH(B16,Dipendenti!A:A,0))<$D$2, (MONTH($D$3)-MONTH($D$2))*2.83*(INDEX(Dipendenti!O:O,MATCH(B16,Dipendenti!A:A,0))/6), IF(DAY(INDEX(Dipendenti!H:H,MATCH(B16,Dipendenti!A:A,0)))<15, (MONTH($D$3)-MONTH(INDEX(Dipendenti!H:H,MATCH(B16,Dipendenti!A:A,0))))*2.83*(INDEX(Dipendenti!O:O,MATCH(B16,Dipendenti!A:A,0))/6), ((MONTH($D$3)-MONTH(INDEX(Dipendenti!H:H,MATCH(B16,Dipendenti!A:A,0))))*2.83*(INDEX(Dipendenti!O:O,MATCH(B16,Dipendenti!A:A,0))/6)+ ((_xlfn.DAYS(EOMONTH(INDEX(Dipendenti!H:H,MATCH(B16,Dipendenti!A:A,0)),0), INDEX(Dipendenti!H:H,MATCH(B16,Dipendenti!A:A,0)))+1)/(_xlfn.DAYS(EOMONTH(INDEX(Dipendenti!H:H,MATCH(B16,Dipendenti!A:A,0)),0), EOMONTH(INDEX(Dipendenti!H:H,MATCH(B16,Dipendenti!A:A,0)),-1)+1)+1) )*2.83*(INDEX(Dipendenti!O:O,MATCH(B16,Dipendenti!A:A,0))/6) ) ) )) -> 0 | E16: =IF($B16="","",COUNTIFS(ChiusureAziendali!$A:$A,">"&$D$2,ChiusureAziendali!$A:$A,"<="&$D$3)*7.12) -> 0 | F16: =IF($B16="","",SUMIFS(Registro_Ferie!$C:$C, Registro_Ferie!$A:$A,$B16, Registro_Ferie!$D:$D, "ferie_g", Registro_Ferie!$B:$B, ">="&$D$2, Registro_Ferie!$C:$C, "<="&$D$3) + SUMIFS(Registro_Ferie!$C:$C, Registro_Ferie!$A:$A,$B16, Registro_Ferie!$D:$D, "ferie_g", Registro_Ferie!$B:$B, ">="&$D$2, Registro_Ferie!$B:$B, "<="&$D$3)) -> 0 | G16: =IFERROR($F16 / (INDEX(Dipendenti!$O:$O, MATCH($B16, Dipendenti!$A:$A, 0)) / 6), "") -> 0 | H16: =IF($B16="","",SUMIFS(Registro_Ferie!$C:$C, Registro_Ferie!$A:$A,$B16, Registro_Ferie!$D:$D, "ferie", Registro_Ferie!$B:$B, ">="&$D$2, Registro_Ferie!$C:$C, "<="&$D$3) + SUMIFS(Registro_Ferie!$C:$C, Registro_Ferie!$A:$A,$B16, Registro_Ferie!$D:$D, "ferie", Registro_Ferie!$B:$B, ">="&$D$2, Registro_Ferie!$B:$B, "<="&$D$3)) -> 0 | I16: =IFERROR(C16+D16-E16-F16-H16,"") -> 180 | J16: =IFERROR($I16 / (INDEX(Dipendenti!$O:$O, MATCH($B16, Dipendenti!$A:$A, 0)) / 5), "") -> 25
B17: {=IFERROR(INDEX(Dipendenti!A$2:A$548, SMALL(IF( (Dipendenti!G$2:G$548 = $D$4) * (Dipendenti!G$2:G$548 <> "") * (Dipendenti!L$2:L$548 <> "Lib Prof") * (IF(Dipendenti!J$2:J$548 = "", TRUE, Dipendenti!J$2:J$548 >= $D$3)), ROW(Dipendenti!A$2:A$548) - ROW(Dipendenti!A$2) + 1), ROW(A10))), "")} -> Sara Bruno | C17: =IFERROR(VLOOKUP($B17,SaldiFerie!A:C,3,FALSE),"") -> 18 | D17: =IF(B17="","",IF(INDEX(Dipendenti!H:H,MATCH(B17,Dipendenti!A:A,0))<$D$2, (MONTH($D$3)-MONTH($D$2))*2.83*(INDEX(Dipendenti!O:O,MATCH(B17,Dipendenti!A:A,0))/6), IF(DAY(INDEX(Dipendenti!H:H,MATCH(B17,Dipendenti!A:A,0)))<15, (MONTH($D$3)-MONTH(INDEX(Dipendenti!H:H,MATCH(B17,Dipendenti!A:A,0))))*2.83*(INDEX(Dipendenti!O:O,MATCH(B17,Dipendenti!A:A,0))/6), ((MONTH($D$3)-MONTH(INDEX(Dipendenti!H:H,MATCH(B17,Dipendenti!A:A,0))))*2.83*(INDEX(Dipendenti!O:O,MATCH(B17,Dipendenti!A:A,0))/6)+ ((_xlfn.DAYS(EOMONTH(INDEX(Dipendenti!H:H,MATCH(B17,Dipendenti!A:A,0)),0), INDEX(Dipendenti!H:H,MATCH(B17,Dipendenti!A:A,0)))+1)/(_xlfn.DAYS(EOMONTH(INDEX(Dipendenti!H:H,MATCH(B17,Dipendenti!A:A,0)),0), EOMONTH(INDEX(Dipendenti!H:H,MATCH(B17,Dipendenti!A:A,0)),-1)+1)+1) )*2.83*(INDEX(Dipendenti!O:O,MATCH(B17,Dipendenti!A:A,0))/6) ) ) )) -> 0 | E17: =IF($B17="","",COUNTIFS(ChiusureAziendali!$A:$A,">"&$D$2,ChiusureAziendali!$A:$A,"<="&$D$3)*7.12) -> 0 | F17: =IF($B17="","",SUMIFS(Registro_Ferie!$C:$C, Registro_Ferie!$A:$A,$B17, Registro_Ferie!$D:$D, "ferie_g", Registro_Ferie!$B:$B, ">="&$D$2, Registro_Ferie!$C:$C, "<="&$D$3) + SUMIFS(Registro_Ferie!$C:$C, Registro_Ferie!$A:$A,$B17, Registro_Ferie!$D:$D, "ferie_g", Registro_Ferie!$B:$B, ">="&$D$2, Registro_Ferie!$B:$B, "<="&$D$3)) -> 63.59 | G17: =IFERROR($F17 / (INDEX(Dipendenti!$O:$O, MATCH($B17, Dipendenti!$A:$A, 0)) / 6), "") -> 10.598333 | H17: =IF($B17="","",SUMIFS(Registro_Ferie!$C:$C, Registro_Ferie!$A:$A,$B17, Registro_Ferie!$D:$D, "ferie", Registro_Ferie!$B:$B, ">="&$D$2, Registro_Ferie!$C:$C, "<="&$D$3) + SUMIFS(Registro_Ferie!$C:$C, Registro_Ferie!$A:$A,$B17, Registro_Ferie!$D:$D, "ferie", Registro_Ferie!$B:$B, ">="&$D$2, Registro_Ferie!$B:$B, "<="&$D$3)) -> 0 | I17: =IFERROR(C17+D17-E17-F17-H17,"") -> -45.59 | J17: =IFERROR($I17 / (INDEX(Dipendenti!$O:$O, MATCH($B17, Dipendenti!$A:$A, 0)) / 5), "") -> -6.3319444
B18: {=IFERROR(INDEX(Dipendenti!A$2:A$548, SMALL(IF( (Dipendenti!G$2:G$548 = $D$4) * (Dipendenti!G$2:G$548 <> "") * (Dipendenti!L$2:L$548 <> "Lib Prof") * (IF(Dipendenti!J$2:J$548 = "", TRUE, Dipendenti!J$2:J$548 >= $D$3)), ROW(Dipendenti!A$2:A$548) - ROW(Dipendenti!A$2) + 1), ROW(A11))), "")} -> Simone Russo | C18: =IFERROR(VLOOKUP($B18,SaldiFerie!A:C,3,FALSE),"") -> 180 | D18: =IF(B18="","",IF(INDEX(Dipendenti!H:H,MATCH(B18,Dipendenti!A:A,0))<$D$2, (MONTH($D$3)-MONTH($D$2))*2.83*(INDEX(Dipendenti!O:O,MATCH(B18,Dipendenti!A:A,0))/6), IF(DAY(INDEX(Dipendenti!H:H,MATCH(B18,Dipendenti!A:A,0)))<15, (MONTH($D$3)-MONTH(INDEX(Dipendenti!H:H,MATCH(B18,Dipendenti!A:A,0))))*2.83*(INDEX(Dipendenti!O:O,MATCH(B18,Dipendenti!A:A,0))/6), ((MONTH($D$3)-MONTH(INDEX(Dipendenti!H:H,MATCH(B18,Dipendenti!A:A,0))))*2.83*(INDEX(Dipendenti!O:O,MATCH(B18,Dipendenti!A:A,0))/6)+ ((_xlfn.DAYS(EOMONTH(INDEX(Dipendenti!H:H,MATCH(B18,Dipendenti!A:A,0)),0), INDEX(Dipendenti!H:H,MATCH(B18,Dipendenti!A:A,0)))+1)/(_xlfn.DAYS(EOMONTH(INDEX(Dipendenti!H:H,MATCH(B18,Dipendenti!A:A,0)),0), EOMONTH(INDEX(Dipendenti!H:H,MATCH(B18,Dipendenti!A:A,0)),-1)+1)+1) )*2.83*(INDEX(Dipendenti!O:O,MATCH(B18,Dipendenti!A:A,0))/6) ) ) )) -> 0 | E18: =IF($B18="","",COUNTIFS(ChiusureAziendali!$A:$A,">"&$D$2,ChiusureAziendali!$A:$A,"<="&$D$3)*7.12) -> 0 | F18: =IF($B18="","",SUMIFS(Registro_Ferie!$C:$C, Registro_Ferie!$A:$A,$B18, Registro_Ferie!$D:$D, "ferie_g", Registro_Ferie!$B:$B, ">="&$D$2, Registro_Ferie!$C:$C, "<="&$D$3) + SUMIFS(Registro_Ferie!$C:$C, Registro_Ferie!$A:$A,$B18, Registro_Ferie!$D:$D, "ferie_g", Registro_Ferie!$B:$B, ">="&$D$2, Registro_Ferie!$B:$B, "<="&$D$3)) -> 56.38 | G18: =IFERROR($F18 / (INDEX(Dipendenti!$O:$O, MATCH($B18, Dipendenti!$A:$A, 0)) / 6), "") -> 9.3966667 | H18: =IF($B18="","",SUMIFS(Registro_Ferie!$C:$C, Registro_Ferie!$A:$A,$B18, Registro_Ferie!$D:$D, "ferie", Registro_Ferie!$B:$B, ">="&$D$2, Registro_Ferie!$C:$C, "<="&$D$3) + SUMIFS(Registro_Ferie!$C:$C, Registro_Ferie!$A:$A,$B18, Registro_Ferie!$D:$D, "ferie", Registro_Ferie!$B:$B, ">="&$D$2, Registro_Ferie!$B:$B, "<="&$D$3)) -> 0 | I18: =IFERROR(C18+D18-E18-F18-H18,"") -> 123.62 | J18: =IFERROR($I18 / (INDEX(Dipendenti!$O:$O, MATCH($B18, Dipendenti!$A:$A, 0)) / 5), "") -> 17.169444
B19: {=IFERROR(INDEX(Dipendenti!A$2:A$548, SMALL(IF( (Dipendenti!G$2:G$548 = $D$4) * (Dipendenti!G$2:G$548 <> "") * (Dipendenti!L$2:L$548 <> "Lib Prof") * (IF(Dipendenti!J$2:J$548 = "", TRUE, Dipendenti!J$2:J$548 >= $D$3)), ROW(Dipendenti!A$2:A$548) - ROW(Dipendenti!A$2) + 1), ROW(A12))), "")} -> Valentina Ferrari | C19: =IFERROR(VLOOKUP($B19,SaldiFerie!A:C,3,FALSE),"") -> -30 | D19: =IF(B19="","",IF(INDEX(Dipendenti!H:H,MATCH(B19,Dipendenti!A:A,0))<$D$2, (MONTH($D$3)-MONTH($D$2))*2.83*(INDEX(Dipendenti!O:O,MATCH(B19,Dipendenti!A:A,0))/6), IF(DAY(INDEX(Dipendenti!H:H,MATCH(B19,Dipendenti!A:A,0)))<15, (MONTH($D$3)-MONTH(INDEX(Dipendenti!H:H,MATCH(B19,Dipendenti!A:A,0))))*2.83*(INDEX(Dipendenti!O:O,MATCH(B19,Dipendenti!A:A,0))/6), ((MONTH($D$3)-MONTH(INDEX(Dipendenti!H:H,MATCH(B19,Dipendenti!A:A,0))))*2.83*(INDEX(Dipendenti!O:O,MATCH(B19,Dipendenti!A:A,0))/6)+ ((_xlfn.DAYS(EOMONTH(INDEX(Dipendenti!H:H,MATCH(B19,Dipendenti!A:A,0)),0), INDEX(Dipendenti!H:H,MATCH(B19,Dipendenti!A:A,0)))+1)/(_xlfn.DAYS(EOMONTH(INDEX(Dipendenti!H:H,MATCH(B19,Dipendenti!A:A,0)),0), EOMONTH(INDEX(Dipendenti!H:H,MATCH(B19,Dipendenti!A:A,0)),-1)+1)+1) )*2.83*(INDEX(Dipendenti!O:O,MATCH(B19,Dipendenti!A:A,0))/6) ) ) )) -> 0 | E19: =IF($B19="","",COUNTIFS(ChiusureAziendali!$A:$A,">"&$D$2,ChiusureAziendali!$A:$A,"<="&$D$3)*7.12) -> 0 | F19: =IF($B19="","",SUMIFS(Registro_Ferie!$C:$C, Registro_Ferie!$A:$A,$B19, Registro_Ferie!$D:$D, "ferie_g", Registro_Ferie!$B:$B, ">="&$D$2, Registro_Ferie!$C:$C, "<="&$D$3) + SUMIFS(Registro_Ferie!$C:$C, Registro_Ferie!$A:$A,$B19, Registro_Ferie!$D:$D, "ferie_g", Registro_Ferie!$B:$B, ">="&$D$2, Registro_Ferie!$B:$B, "<="&$D$3)) -> 100.44 | G19: =IFERROR($F19 / (INDEX(Dipendenti!$O:$O, MATCH($B19, Dipendenti!$A:$A, 0)) / 6), "") -> 16.74 | H19: =IF($B19="","",SUMIFS(Registro_Ferie!$C:$C, Registro_Ferie!$A:$A,$B19, Registro_Ferie!$D:$D, "ferie", Registro_Ferie!$B:$B, ">="&$D$2, Registro_Ferie!$C:$C, "<="&$D$3) + SUMIFS(Registro_Ferie!$C:$C, Registro_Ferie!$A:$A,$B19, Registro_Ferie!$D:$D, "ferie", Registro_Ferie!$B:$B, ">="&$D$2, Registro_Ferie!$B:$B, "<="&$D$3)) -> 0 | I19: =IFERROR(C19+D19-E19-F19-H19,"") -> -130.44 | J19: =IFERROR($I19 / (INDEX(Dipendenti!$O:$O, MATCH($B19, Dipendenti!$A:$A, 0)) / 5), "") -> -18.116667
